Workbook
Name __Fieldmark__27_1863259733: 'INVOICE 94'!#REF!

Sheet Kangatang

Sheet packinglist
A2: PACKING LIST
A3: ='[2]commercial '!A2:C2 -> Seller : | D3: ='[2]commercial '!D2 -> Invoice No. and date : | E3: =+#REF! -> #REF!
A4: SCAVI HUE COMPANY | D4: 44455
A5: PHONG DIEN INDUSTRIAL ZONE, PHONG DIEN DISTRICT | D5: Term payment:
A6: THUA THIEN HUE PROVINCE, VIETNAM
A7: Consignee : | D7: Buyer :
A8: SUPREME MUNSINGWEAR CANADA INC. | D8: PEI VIETNAM OFFICE
A9: 1938 AVENUE RD - 2ND FLOOR, ONTARIO, TORONTO, M5M 4A1 | D9: F12, 24C Phan Dang Luu Street, Ward 06, Binh Thanh District,
A10: CANADA | D10: Ho Chi Minh, 70000, VIETNAM
A11: Notify : | D11: Actual manufacturer :
A12: SUPREME MUNSINGWEAR CANADA INC. | D12: F2526-SCAVI HUE COMPANY
A13: 1938 AVENUE RD - 2ND FLOOR, ONTARIO, TORONTO, M5M 4A1 | D13: PHONG DIEN INDUSTRIAL ZONE,
A14: CANADA | D14: PHONG DIEN TOWN, PHONG DIEN DISTRICT, PHONG DIEN, 530000
D15: VIETNAM
A16: PORT OF DEPARTURE: | B16: VANCOUVER, BC | D16: Other references
A17: ='[2]commercial '!A15 -> VESSEL NO: | B17: YM INITIATIVE 283N | D17: Country of origin: | E17: VIETNAM
A18: ='[2]commercial '!A16 -> FCR NO:
A19: Departure date : | D19: Term of delivery and payment:
A20: TO/ DESTINATION : | B20: TORONTO, ON | D20: FOB
A21: Shipping marks : | B21: No. & kind of pkgs : Good description | D21: Quantity | E21: Gross weight | F21: Measurement
B22: PO | C22: 03SU2932
B23: NESSC318 | C23: SWIMWEAR | D23: 820 | E23: 146.57 | F23: 0.99658171
A24: PEI | B24: NESSC318 | C24: SWIMWEAR | D24: 725 | E24: 127.36 | F24: 0.87476223
A25: STYLE#: | B25: NESSC320 | C25: SWIMWEAR | D25: 110 | E25: 16.4 | F25: 0.21218717
A26: P.O.: | B26: NESSC328 | C26: SWIMWEAR | D26: 671 | E26: 169.48 | F26: 1.6796574
A27: N.W.: KGS | B27: NESSC328 | C27: SWIMWEAR | D27: 85 | E27: 21.72 | F27: 0.21628665
A28: G.W.: KGS | B28: NESSC328 | C28: SWIMWEAR | D28: 671 | E28: 169.636 | F28: 1.6796574
A29: CARTON DIMENSION: INCH | B29: NESSC329 | C29: SWIMWEAR | D29: 671 | E29: 166.3 | F29: 1.7788132
A30: SIZE | B30: NESSC329 | C30: SWIMWEAR | D30: 671 | E30: 164.64 | F30: 1.7788132
A31: QTY | B31: NESSC330 | C31: SWIMWEAR | D31: 80 | E31: 13.88 | F31: 0.16833007
A32: COLOR NAME/ CODE: | B32: NESSC332 | C32: SWIMWEAR | D32: 769 | E32: 95.895833 | F32: 1.4839256
B33: NESSC332 | C33: SWIMWEAR | D33: 766 | E33: 92.96138 | F33: 1.4839256
D35: =SUM(D23:D34) -> 6039 | E35: =SUM(E23:E34) -> 1184.8432 | F35: =SUM(F23:F34) -> 12.35294
A36: PACKING INSTRUCTIONS: FOLD PACKED
A37: * WE HEREBY CERTIFY THAT EACH CARTON IS MARKED ON THE OUTSIDE WITH AT MINIMUM THE
A38: CORRESPONDING PURCHASE ORDER NUMBER, STYLE, SIZE(S), AND COLORS CONTAINED IN THE CARTON, NET AND
A39: GROSS WEIGHT AND CUBIC MEASUREMENTS, AS WELL AS ANY OTHER MARKINGS REQUIRED BY CORRESPONDING
A40: PURCHASE ORDER.
A41: THIS IS CERTIFY THAT THE NAME OF MANUFACTURER DOES NOT APPEAR ON THE CARTONS AND THAT NO
A42: IRREGULAR CARTONS HAVE BEEN SHIPPED.
...

Sheet INVOICE 94
A1: COMMERCIAL INVOICE
A2: Shipper: | C2: B'LAO SPORT COMPANY LIMITED | K2: Invoice No. and date: | M2: =+N2 -> 7726477 | N2: 7726477
C3: Lot CN 37B, Zone C, Phong Dien Industrial Zone, | M3: 46120
C4: Phong Thu Ward, Phong Dien Town, Hue City, Vietnam | K4: Method of Payment: | M4: By Trade Card
C6: TAX | E6: 3301677376
A7: Consignee: | C7: SUPREME INTERNATIONAL, LLC | K7: Buyer (if other than consignee):
C8: 3000 NW 107TH AVENUE
C9: DORAL, FL 33172 | L9: Same as consignee
C10: UNITED STATES OF AMERICA
A12: Notify Party: | K12: Other references:
C13: SINGAPORE UNISERVE EGDC, UNISERVE EDGC SINGAPORE ,
C14: 27 Greenwich Drive, #1M,OFC- #02-0, WHS, SINGAPORE, 533912, SINGAPORE | K14: DIVISION CODE: | M14: SWM
A16: Final Destination: | K16: Actual manufacturer
A17: SINGAPORE UNISERVE EGDC, UNISERVE EDGC SINGAPORE ,
A18: 27 Greenwich Drive, #1M,OFC- #02-0, WHS, SINGAPORE, 533912, SINGAPORE
A20: Departure date: | B20: 46033 | F20: From: | G20: DA NANG PORT | K20: M.I.D. CODE
A22: Vessel: | B22: YM HORIZON 413S | F22: To: | G22: SINGAPORE | K22: Term of delivery :
K23: FOB VIETNAM
A24: BL NO.: | Q24: DONG FANG FU 2420N
A25: PO | B25: Reference | C25: Color | D25: GENDER | E25: Composision | H25: Carton | I25: Carton Small | J25: Quantity | K25: Unit price (USD) | M25: Amount (USD ) | O25: CO FORM
A27: GIRL/MISSY- KNIT-SWIMWEAR
A29: AJ916 | B29: NESSG277 | C29: BLACK | D29: GIRL | E29: =+VLOOKUP(B29,'[3]danh muc PERRY, YMM'!F$2625:G$2747,2,0) -> 82/18 POLYESTER/ELASTANE | H29: 4 | I29: 4 | J29: 100 | K29: =+VLOOKUP(N29,'[4]he thong'!A$1:G$45,7,0) -> 3.42 | M29: =+K29*J29 -> 342 | N29: 800005744
A30: AJ916 | B30: NESSG278 | C30: BLACK | D30: GIRL | E30: =+VLOOKUP(B30,'[3]danh muc PERRY, YMM'!F$2625:G$2747,2,0) -> 82/18 POLYESTER/ELASTANE | H30: 7 | I30: 7 | J30: 200 | K30: =+VLOOKUP(N30,'[4]he thong'!A$1:G$45,7,0) -> 3.72 | M30: =+K30*J30 -> 744 | N30: 800005745
A31: DV10 | B31: NESSB711 | C31: BLACK | E31: =+VLOOKUP(B31,'[3]danh muc PERRY, YMM'!F$2625:G$2747,2,0) -> 80/20 POLYAMIDE/ELASTANE | H31: 15 | I31: 16 | J31: 500 | K31: =+VLOOKUP(N31,'[4]he thong'!A$1:G$45,7,0) -> 3.78 | M31: =+K31*J31 -> 1890 | N31: 800005535
A32: DV10 | B32: NESSB711 | C32: DESERT PINK | E32: =+VLOOKUP(B32,'[3]danh muc PERRY, YMM'!F$2625:G$2747,2,0) -> 80/20 POLYAMIDE/ELASTANE | H32: 8 | I32: 8 | J32: 250 | K32: =+VLOOKUP(N32,'[4]he thong'!A$1:G$45,7,0) -> 3.83 | M32: =+K32*J32 -> 957.5 | N32: 800005507
A33: DV6 | B33: NESSB711 | C33: BLACK | E33: =+VLOOKUP(B33,'[3]danh muc PERRY, YMM'!F$2625:G$2747,2,0) -> 80/20 POLYAMIDE/ELASTANE | H33: 30 | I33: 30 | J33: 990 | K33: =+VLOOKUP(N33,'[4]he thong'!A$1:G$45,7,0) -> 3.78 | M33: =+K33*J33 -> 3742.2 | N33: 800005536
A34: DV6 | B34: NESSB711 | C34: DESERT PINK | E34: =+VLOOKUP(B34,'[3]danh muc PERRY, YMM'!F$2625:G$2747,2,0) -> 80/20 POLYAMIDE/ELASTANE | H34: 15 | I34: 16 | J34: 500 | K34: =+VLOOKUP(N34,'[4]he thong'!A$1:G$45,7,0) -> 3.83 | M34: =+K34*J34 -> 1915 | N34: 800005537
A35: DV7 | B35: NESSB711 | C35: BLACK | E35: =+VLOOKUP(B35,'[3]danh muc PERRY, YMM'!F$2625:G$2747,2,0) -> 80/20 POLYAMIDE/ELASTANE | H35: 15 | I35: 16 | J35: 500 | K35: =+VLOOKUP(N35,'[4]he thong'!A$1:G$45,7,0) -> 3.78 | M35: =+K35*J35 -> 1890 | N35: 800005540
A36: DV7 | B36: NESSB711 | C36: DESERT PINK | E36: =+VLOOKUP(B36,'[3]danh muc PERRY, YMM'!F$2625:G$2747,2,0) -> 80/20 POLYAMIDE/ELASTANE | H36: 8 | I36: 8 | J36: 250 | K36: =+VLOOKUP(N36,'[4]he thong'!A$1:G$45,7,0) -> 3.83 | M36: =+K36*J36 -> 957.5 | N36: 800005541
A37: EQ349 | B37: NESSB711 | C37: ENERGY | E37: =+VLOOKUP(B37,'[3]danh muc PERRY, YMM'!F$2625:G$2747,2,0) -> 80/20 POLYAMIDE/ELASTANE | H37: 3 | I37: 4 | J37: 48 | K37: =+VLOOKUP(N37,'[4]he thong'!A$1:G$45,7,0) -> 3.81 | M37: =+K37*J37 -> 182.88 | N37: 800005754
A38: EV154 | B38: NESSB711 | C38: BLACK | E38: =+VLOOKUP(B38,'[3]danh muc PERRY, YMM'!F$2625:G$2747,2,0) -> 80/20 POLYAMIDE/ELASTANE | H38: 5 | I38: 5 | J38: 120 | K38: =+VLOOKUP(N38,'[4]he thong'!A$1:G$45,7,0) -> 3.75 | M38: =+K38*J38 -> 450 | N38: 800005755
A39: EV154 | B39: NESSB711 | C39: ENERGY | E39: =+VLOOKUP(B39,'[3]danh muc PERRY, YMM'!F$2625:G$2747,2,0) -> 80/20 POLYAMIDE/ELASTANE | H39: 5 | I39: 5 | J39: 120 | K39: =+VLOOKUP(N39,'[4]he thong'!A$1:G$45,7,0) -> 3.8 | M39: =+K39*J39 -> 456 | N39: 800005756
A40: EV154 | B40: NESSB711 | C40: DESERT PINK | E40: =+VLOOKUP(B40,'[3]danh muc PERRY, YMM'!F$2625:G$2747,2,0) -> 80/20 POLYAMIDE/ELASTANE | H40: 5 | I40: 5 | J40: 120 | K40: =+VLOOKUP(N40,'[4]he thong'!A$1:G$45,7,0) -> 3.8 | M40: =+K40*J40 -> 456 | N40: 800005757
A41: EV154 | B41: NESSG730 | C41: BLACK | E41: =+VLOOKUP(B41,'[3]danh muc PERRY, YMM'!F$2625:G$2747,2,0) -> 80/20 POLYAMIDE/ELASTANE | H41: 5 | I41: 5 | J41: 96 | K41: =+VLOOKUP(N41,'[4]he thong'!A$1:G$45,7,0) -> 5.18 | M41: =+K41*J41 -> 497.28 | N41: 800005758
A42: EV154 | B42: NESSG730 | C42: DESERT PINK | E42: =+VLOOKUP(B42,'[3]danh muc PERRY, YMM'!F$2625:G$2747,2,0) -> 80/20 POLYAMIDE/ELASTANE | H42: 5 | I42: 5 | J42: 96 | K42: =+VLOOKUP(N42,'[4]he thong'!A$1:G$45,7,0) -> 5.42 | M42: =+K42*J42 -> 520.32 | N42: 800005759
... A71: XL102 | B71: NESSB711 | C71: DESERT PINK | E71: =+VLOOKUP(B71,'[3]danh muc PERRY, YMM'!F$2625:G$2747,2,0) -> 80/20 POLYAMIDE/ELASTANE | H71: 1 | I71: 4 | J71: 24 | K71: =+VLOOKUP(N71,'[4]he thong'!A$1:G$45,7,0) -> 3.81 | M71: =+K71*J71 -> 91.44 | N71: 800005787
H74: =SUM(H29:H73) -> 243 | I74: =SUM(I29:I73) -> 282 | J74: =SUM(J29:J73) -> 6266 | M74: =SUM(M29:M73) -> 26432.36
A77: SAY TOTAL US DOLLARS | B77: {=+UPPER(_xll.USD(M74))} -> TWENTY SIX THOUSAND FOUR HUNDRED AND THIRTY TWO DOLLARS AND THIRTY SIX CENTS.
A78: TTL: | B78: =+H74 -> 243
A81: *WE HEREBY CERTIFY THAT THE FABRIC IS PIECE DYED AND THERE IS SOLID COLOR IN THE WARP AND FILLINGS.
...

Sheet AJ916
A1: B'LAO SPORT COMPANY LIMITED
A2: Lot CN 37B, Zone C, Phong Dien Industrial Zone,
A3: Phong Thu Ward, Phong Dien Town, Hue City, Vietnam
A5: DETAIL BREAKDOWN - By MASTER BOX
A6: PO# | B6: AJ916
A7: CTNS: | B7: =+L24 -> 11
A9: STYLE | B9: COLOR | C9: COLOR CODE | D9: CASE FROM- TO | F9: Units/case | G9: xs | H9: S | I9: M | J9: L | K9: XL | L9: TOT CTNS | M9: TOT PCS | N9: GW | O9: DIM
A10: NESSG277 | B10: 001 BLACK | C10: 001 | D10: 1 | E10: 1 | F10: 5 | G10: 5 | L10: 1 | M10: 5 | N10: 0.84 | O10: 43.18*41.91*7.62 | P10: 9 | Q10: 9 | R10: 3 | S10: =+P10*2.54 -> 22.86 | T10: =+Q10*2.54 -> 22.86 | U10: =+R10*2.54 -> 7.62 | V10: =S10&"*"&T10&"*"&U10 -> 22.86*22.86*7.62
A11: NESSG277 | B11: 001 BLACK | C11: 001 | D11: 2 | E11: 2 | F11: 27 | H11: 27 | L11: 1 | M11: 27 | N11: 2.76 | O11: 43.18*41.91*7.62 | P11: 16 | Q11: 15.5 | R11: 4 | S11: =+P11*2.54 -> 40.64 | T11: =+Q11*2.54 -> 39.37 | U11: =+R11*2.54 -> 10.16 | V11: =S11&"*"&T11&"*"&U11 -> 40.64*39.37*10.16
A12: NESSG277 | B12: 001 BLACK | C12: 001 | D12: 3 | E12: 3 | F12: 35 | I12: 35 | L12: 1 | M12: 35 | N12: 3.84 | O12: 43.18*41.91*7.62 | P12: 16 | Q12: 15 | R12: 4.5 | S12: =+P12*2.54 -> 40.64 | T12: =+Q12*2.54 -> 38.1 | U12: =+R12*2.54 -> 11.43 | V12: =S12&"*"&T12&"*"&U12 -> 40.64*38.1*11.43
A13: NESSG277 | B13: 001 BLACK | C13: 001 | D13: 4 | E13: 4 | F13: 33 | J13: 33 | L13: 1 | M13: 33 | N13: 4.11 | O13: 44.45*44.45*8.89 | P13: 16 | Q13: 15 | R13: 5.5 | S13: =+P13*2.54 -> 40.64 | T13: =+Q13*2.54 -> 38.1 | U13: =+R13*2.54 -> 13.97 | V13: =S13&"*"&T13&"*"&U13 -> 40.64*38.1*13.97
L14: 4 | M14: 100 | N14: 11.55 | S14: =+P14*2.54 -> 0 | T14: =+Q14*2.54 -> 0 | U14: =+R14*2.54 -> 0 | V14: =S14&"*"&T14&"*"&U14 -> 0*0*0
A15: NESSG278 | B15: 001 BLACK | C15: 001 | D15: 5 | E15: 5 | F15: 36 | H15: 36 | L15: 1 | M15: 36 | N15: 3.9 | O15: 43.18*41.91*7.62 | P15: 16 | Q15: 15 | R15: 7.5 | S15: =+P15*2.54 -> 40.64 | T15: =+Q15*2.54 -> 38.1 | U15: =+R15*2.54 -> 19.05 | V15: =S15&"*"&T15&"*"&U15 -> 40.64*38.1*19.05
A16: NESSG278 | B16: 001 BLACK | C16: 001 | D16: 6 | E16: 6 | F16: 36 | I16: 36 | L16: 1 | M16: 36 | N16: 4.14 | O16: 43.18*41.91*7.62 | P16: 16 | Q16: 15 | R16: 7.5 | S16: =+P16*2.54 -> 40.64 | T16: =+Q16*2.54 -> 38.1 | U16: =+R16*2.54 -> 19.05 | V16: =S16&"*"&T16&"*"&U16 -> 40.64*38.1*19.05
A17: NESSG278 | B17: 001 BLACK | C17: 001 | D17: 7 | E17: 7 | F17: 36 | J17: 36 | L17: 1 | M17: 36 | N17: 4.41 | O17: 43.18*41.91*7.62 | P17: 16 | Q17: 15 | R17: 7.5 | S17: =+P17*2.54 -> 40.64 | T17: =+Q17*2.54 -> 38.1 | U17: =+R17*2.54 -> 19.05 | V17: =S17&"*"&T17&"*"&U17 -> 40.64*38.1*19.05
A18: NESSG278 | B18: 001 BLACK | C18: 001 | D18: 8 | E18: 8 | F18: 26 | G18: 26 | L18: 1 | M18: 26 | N18: 2.665 | O18: 44.45*44.45*8.89 | P18: 16 | Q18: 15 | R18: 5.5 | S18: =+P18*2.54 -> 40.64 | T18: =+Q18*2.54 -> 38.1 | U18: =+R18*2.54 -> 13.97 | V18: =S18&"*"&T18&"*"&U18 -> 40.64*38.1*13.97
A19: NESSG278 | B19: 001 BLACK | C19: 001 | D19: 9 | E19: 9 | F19: 14 | H19: 14 | L19: 1 | M19: 14 | N19: 1.5166667 | O19: 44.45*44.45*8.89 | P19: 16 | Q19: 15.5 | R19: 3 | S19: =+P19*2.54 -> 40.64 | T19: =+Q19*2.54 -> 39.37 | U19: =+R19*2.54 -> 7.62 | V19: =S19&"*"&T19&"*"&U19 -> 40.64*39.37*7.62
A20: NESSG278 | B20: 001 BLACK | C20: 001 | D20: 10 | E20: 10 | F20: 34 | I20: 34 | L20: 1 | M20: 34 | N20: 3.91 | O20: 44.45*44.45*8.89 | P20: 16 | Q20: 15 | R20: 7.5 | S20: =+P20*2.54 -> 40.64 | T20: =+Q20*2.54 -> 38.1 | U20: =+R20*2.54 -> 19.05 | V20: =S20&"*"&T20&"*"&U20 -> 40.64*38.1*19.05
A21: NESSG278 | B21: 001 BLACK | C21: 001 | D21: 11 | E21: 11 | F21: 18 | J21: 18 | L21: 1 | M21: 18 | N21: 2.205 | O21: 44.45*44.45*8.89 | P21: 16 | Q21: 15.5 | R21: 4 | S21: =+P21*2.54 -> 40.64 | T21: =+Q21*2.54 -> 39.37 | U21: =+R21*2.54 -> 10.16 | V21: =S21&"*"&T21&"*"&U21 -> 40.64*39.37*10.16
L22: 7 | M22: 200 | N22: 22.746667 | S22: =+P22*2.54 -> 0 | T22: =+Q22*2.54 -> 0 | U22: =+R22*2.54 -> 0 | V22: =S22&"*"&T22&"*"&U22 -> 0*0*0
L24: =+L22+L14 -> 11 | M24: =+M22+M14 -> 300 | N24: =+N22+N14 -> 34.296667

Sheet PLS AJ916
A1: PACKING LIST - By MASTER BOX
A2: SUMMARY BREAKDOWN
A4: PO# | B4: =+'AJ916'!B6 -> AJ916
A5: CTNS: | B5: =+I10 -> 11
A6: STYLE | B6: COLOR | C6: COLOR CODE | D6: xs | E6: S | F6: M | G6: L | H6: XL | I6: TOT CTNS | J6: TOT PCS
A7: NESSG277 | B7: BLACK | C7: 001 | D7: 5 | E7: 27 | F7: 35 | G7: 33 | I7: 4 | J7: 100 | K7: =+SUM(D7:H7) -> 100 | L7: =+K7-J7 -> 0
A8: NESSG278 | B8: BLACK | C8: 001 | D8: 26 | E8: 50 | F8: 70 | G8: 54 | I8: 7 | J8: 200 | K8: =+SUM(D8:H8) -> 200 | L8: =+K8-J8 -> 0
A10: TOTAL | I10: =SUM(I7:I9) -> 11 | J10: =SUM(J7:J9) -> 300
A11: Carton Specs & Shipment Specs :
A12: Purchase Order: | B12: =+B4 -> AJ916 | C12: GRAND TOTAL | D12: SIGNED BY:
A13: Total cartons: | B13: =+C13 -> 11 | C13: =+I10 -> 11
A14: Total Gross Wt:(kgs) | B14: =+C14/$B$13 -> 3.1178788 | C14: 34.296667
A15: Total Net Wt:(kgs) | B15: =+C15/$B$13 -> 2.4554545 | C15: 27.01
A16: Total Net Net Wt:(kgs)
A17: Empty carton Wt
A18: CMB: | B18: =+C18/$B$13 -> 0.021467909 | C18: 0.236147
A19: Carton Dimensions:
A20: CM
N26: =SUM(N10:N25) -> 0
B286: -52 | C286: -39
B287: -52 | C287: -39
B288: -52 | C288: -39
B289: -52 | C289: -39
B290: -52 | C290: -39
B291: -52 | C291: -39
B292: -52 | C292: -39
A293: TOTAL: | C293: -39
B294: -52 | C294: -39
B296: -52 | C296: -39
B297: -52 | C297: -39
B298: -52 | C298: -39
B299: -52 | C299: -39
B300: -52 | C300: -39
B301: -52 | C301: -39
B302: -52 | C302: -39
B304: 0 | C304: 0
A311: TOTAL:
A312: GRAND TOTAL:

Sheet SOLID PL DV10
A4: PACKING LIST
H5: PEI
A6: ISSUE TO : | E6: =+'[1]INVOICE 11'!C7 -> SUPREME INTERNATIONAL, LLC | H6: STYLE:
H7: LABEL
H8: P.O.:
H9: PCS
H10: SIZES
A12: PAYMENT: T/C | H12: MADE IN
A13: PO NO: | B13: DV10 | H13: C# UP
A14: CUSTOMER PO.: | E14: =+B13 -> DV10
A15: INVOICE NO: | D15: =+'INVOICE 94'!M2 -> 7726477
A16: Detail Breakdown
A18: CASE FROM-TO | D18: REMARKS | E18: Style | F18: Color Name | G18: Color code | H18: Units/case | I18: xs | J18: S | K18: M | L18: L | M18: 4 | N18: 5 | O18: 6 | P18: 6X | Q18: TOT CTNS | R18: TOT PCS | S18: NW | T18: GW | U18: TTL NW | V18: TTL GW | W18: CARTON SIZE ( CM)
A19: 1 | C19: 2 | E19: NESSB711 | F19: 001 BLACK | G19: 001 | H19: 36 | J19: 36 | Q19: 2 | R19: 72 | S19: =+U19/Q19 -> 3.32 | T19: =+V19/Q19 -> 4.32 | U19: 6.64 | V19: 8.64 | W19: =AA19&"*"&AB19&"*"&AC19 -> 50.8*43.18*11.43 | X19: 20 | Y19: 17 | Z19: 4.5 | AA19: =+X19*2.54 -> 50.8 | AB19: =+Y19*2.54 -> 43.18 | AC19: =+Z19*2.54 -> 11.43
A20: 3 | C20: 6 | H20: 36 | K20: 36 | Q20: 4 | R20: 144 | S20: =+U20/Q20 -> 3.64 | T20: =+V20/Q20 -> 4.64 | U20: 14.56 | V20: 18.56 | W20: =AA20&"*"&AB20&"*"&AC20 -> 50.8*43.18*11.43 | X20: 20 | Y20: 17 | Z20: 4.5 | AA20: =+X20*2.54 -> 50.8 | AB20: =+Y20*2.54 -> 43.18 | AC20: =+Z20*2.54 -> 11.43
A21: 7 | C21: 10 | H21: 36 | L21: 36 | Q21: 4 | R21: 144 | S21: =+U21/Q21 -> 3.93 | T21: =+V21/Q21 -> 4.96 | U21: 15.72 | V21: 19.84 | W21: =AA21&"*"&AB21&"*"&AC21 -> 50.8*43.18*12.7 | X21: 20 | Y21: 17 | Z21: 5 | AA21: =+X21*2.54 -> 50.8 | AB21: =+Y21*2.54 -> 43.18 | AC21: =+Z21*2.54 -> 12.7
A22: 11 | C22: 12 | H22: 36 | M22: 36 | Q22: 2 | R22: 72 | S22: =+U22/Q22 -> 4.25 | T22: =+V22/Q22 -> 5.28 | U22: 8.5 | V22: 10.56 | W22: =AA22&"*"&AB22&"*"&AC22 -> 50.8*43.18*12.7 | X22: 20 | Y22: 17 | Z22: 5 | AA22: =+X22*2.54 -> 50.8 | AB22: =+Y22*2.54 -> 43.18 | AC22: =+Z22*2.54 -> 12.7
A23: 13 | C23: 13 | D23: ODD CARTON | H23: 28 | J23: 28 | Q23: 1 | R23: 28 | S23: =+U23/Q23 -> 2.36 | T23: =+V23/Q23 -> 3.36 | U23: 2.36 | V23: 3.36 | W23: =AA23&"*"&AB23&"*"&AC23 -> 50.8*43.18*10.16 | X23: 20 | Y23: 17 | Z23: 4 | AA23: =+X23*2.54 -> 50.8 | AB23: =+Y23*2.54 -> 43.18 | AC23: =+Z23*2.54 -> 10.16
A24: 14 | C24: 14 | D24: ODD CARTON | H24: 28 | M24: 28 | Q24: 1 | R24: 28 | S24: =+U24/Q24 -> 3.1 | T24: =+V24/Q24 -> 4.1 | U24: 3.1 | V24: 4.1 | W24: =AA24&"*"&AB24&"*"&AC24 -> 50.8*43.18*11.43 | X24: 20 | Y24: 17 | Z24: 4.5 | AA24: =+X24*2.54 -> 50.8 | AB24: =+Y24*2.54 -> 43.18 | AC24: =+Z24*2.54 -> 11.43
A25: Master box 15-16 | D25: Master box | X25: 19 | Y25: 11 | Z25: 4.5 | AA25: =+X25*2.54 -> 48.26 | AB25: =+Y25*2.54 -> 27.94 | AC25: =+Z25*2.54 -> 11.43
A26: 15 | C26: 15 | D26: Small box | H26: 6 | K26: 6 | Q26: 1 | R26: 6 | S26: =+U26/Q26 -> 1.75 | T26: =+V26/Q26 -> 2.22 | U26: 1.75 | V26: 2.22 | W26: =AA26&"*"&AB26&"*"&AC26 -> 25.4*22.86*8.89 | X26: 10 | Y26: 9 | Z26: 3.5 | AA26: =+X26*2.54 -> 25.4 | AB26: =+Y26*2.54 -> 22.86 | AC26: =+Z26*2.54 -> 8.89
A27: 16 | C27: 16 | D27: Small box | H27: 6 | L27: 6 | R27: 6 | W27: =AA27&"*"&AB27&"*"&AC27 -> 25.4*22.86*8.89 | X27: 10 | Y27: 9 | Z27: 3.5 | AA27: =+X27*2.54 -> 25.4 | AB27: =+Y27*2.54 -> 22.86 | AC27: =+Z27*2.54 -> 8.89
M28: 100
A29: 17 | C29: 17 | E29: NESSB711 | F29: 655 DESERT PINK | G29: 655 | H29: 36 | J29: 36 | Q29: 1 | R29: 36 | S29: =+U29/Q29 -> 3.32 | T29: =+V29/Q29 -> 4.32 | U29: 3.32 | V29: 4.32 | W29: =AA29&"*"&AB29&"*"&AC29 -> 50.8*43.18*11.43 | X29: 20 | Y29: 17 | Z29: 4.5 | AA29: =+X29*2.54 -> 50.8 | AB29: =+Y29*2.54 -> 43.18 | AC29: =+Z29*2.54 -> 11.43
A30: 18 | C30: 18 | H30: 36 | K30: 36 | Q30: 1 | R30: 36 | S30: =+U30/Q30 -> 3.64 | T30: =+V30/Q30 -> 4.64 | U30: 3.64 | V30: 4.64 | W30: =AA30&"*"&AB30&"*"&AC30 -> 50.8*43.18*11.43 | X30: 20 | Y30: 17 | Z30: 4.5 | AA30: =+X30*2.54 -> 50.8 | AB30: =+Y30*2.54 -> 43.18 | AC30: =+Z30*2.54 -> 11.43
A31: 19 | C31: 19 | H31: 39 | K31: 39 | Q31: 1 | R31: 39 | S31: =+U31/Q31 -> 1.84 | T31: =+V31/Q31 -> 4.84 | U31: 1.84 | V31: 4.84 | W31: =AA31&"*"&AB31&"*"&AC31 -> 50.8*43.18*12.7 | X31: 20 | Y31: 17 | Z31: 5 | AA31: =+X31*2.54 -> 50.8 | AB31: =+Y31*2.54 -> 43.18 | AC31: =+Z31*2.54 -> 12.7
A32: 20 | C32: 20 | H32: 36 | L32: 36 | Q32: 1 | R32: 36 | S32: =+U32/Q32 -> 3.96 | T32: =+V32/Q32 -> 4.96 | U32: 3.96 | V32: 4.96 | W32: =AA32&"*"&AB32&"*"&AC32 -> 50.8*43.18*11.43 | X32: 20 | Y32: 17 | Z32: 4.5 | AA32: =+X32*2.54 -> 50.8 | AB32: =+Y32*2.54 -> 43.18 | AC32: =+Z32*2.54 -> 11.43
A33: 21 | C33: 21 | H33: 39 | L33: 39 | Q33: 1 | R33: 39 | S33: =+U33/Q33 -> 2.02 | T33: =+V33/Q33 -> 5.02 | U33: 2.02 | V33: 5.02 | W33: =AA33&"*"&AB33&"*"&AC33 -> 50.8*43.18*12.7 | X33: 20 | Y33: 17 | Z33: 5 | AA33: =+X33*2.54 -> 50.8 | AB33: =+Y33*2.54 -> 43.18 | AC33: =+Z33*2.54 -> 12.7
A34: 22 | C34: 22 | H34: 36 | M34: 36 | Q34: 1 | R34: 36 | S34: =+U34/Q34 -> 2.28 | T34: =+V34/Q34 -> 5.28 | U34: 2.28 | V34: 5.28 | W34: =AA34&"*"&AB34&"*"&AC34 -> 50.8*43.18*12.7 | X34: 20 | Y34: 17 | Z34: 5 | AA34: =+X34*2.54 -> 50.8 | AB34: =+Y34*2.54 -> 43.18 | AC34: =+Z34*2.54 -> 12.7
A35: 23 | C35: 23 | D35: ODD CARTON | H35: 14 | J35: 14 | Q35: 1 | R35: 14 | S35: =+U35/Q35 -> 1.24 | T35: =+V35/Q35 -> 1.68 | U35: 1.24 | V35: 1.68 | W35: =AA35&"*"&AB35&"*"&AC35 -> 44.45*25.4*7.62 | X35: 17.5 | Y35: 10 | Z35: 3 | AA35: =+X35*2.54 -> 44.45 | AB35: =+Y35*2.54 -> 25.4 | AC35: =+Z35*2.54 -> 7.62
A36: 24 | C36: 24 | D36: ODD CARTON | H36: 14 | M36: 14 | Q36: 1 | R36: 14 | S36: =+U36/Q36 -> 1.61 | T36: =+V36/Q36 -> 2.05 | U36: 1.61 | V36: 2.05 | W36: =AA36&"*"&AB36&"*"&AC36 -> 44.45*25.4*7.62 | X36: 17.5 | Y36: 10 | Z36: 3 | AA36: =+X36*2.54 -> 44.45 | AB36: =+Y36*2.54 -> 25.4 | AC36: =+Z36*2.54 -> 7.62
M37: 50
M39: =SUM(M19:M38) -> 264 | N39: =SUM(N19:N38) -> 0 | O39: =SUM(O19:O38) -> 0 | P39: =SUM(P19:P38) -> 0 | Q39: =SUM(Q19:Q38) -> 23 | R39: =SUM(R19:R38) -> 750 | U39: =SUM(U19:U38) -> 72.54 | V39: =SUM(V19:V38) -> 100.07
D42: CUSTOMER PO | E42: Style | F42: Color | G42: Color Code | H42: xs | I42: S | J42: M | K42: L | L42: XL | Q42: TOT CTNS | R42: TOT PCS
D43: DV10 | E43: NESSB711 | F43: BLACK | G43: 001 | I43: 100 | J43: 150 | K43: 150 | L43: 100 | Q43: 15 | R43: 500 | X43: =+SUM(H43:L43) -> 500 | Y43: =+R43-X43 -> 0
D44: DV10 | E44: NESSB711 | F44: DESERT PINK | G44: 655 | I44: 50 | J44: 75 | K44: 75 | L44: 50 | Q44: 8 | R44: 250 | X44: =+SUM(H44:L44) -> 250 | Y44: =+R44-X44 -> 0
K46: TOTAL | Q46: =SUM(Q43:Q44) -> 23 | R46: =SUM(R43:R44) -> 750

Sheet IRREGULAR SS PLDV10
A4: PACKING LIST
H5: PEI
A6: ISSUE TO : | E6: =+'[1]INVOICE 11'!C7 -> SUPREME INTERNATIONAL, LLC | H6: STYLE:
H7: LABEL
H8: P.O.:
H9: PCS
H10: SIZES
A12: PAYMENT: T/C | H12: MADE IN
A13: PO NO: | B13: DV10 | H13: C# UP
A14: CUSTOMER PO.: | E14: =+B13 -> DV10
A15: INVOICE NO: | D15: =+'INVOICE 94'!M2 -> 7726477
A16: Detail Breakdown
A18: CASE FROM-TO | D18: REMARKS | E18: Style | F18: Color Name | G18: Color code | H18: Units/case | I18: xs | J18: S | K18: M | L18: L | M18: 4 | N18: 5 | O18: 6 | P18: 6X | Q18: TOT CTNS | R18: TOT PCS | S18: NW | T18: GW | U18: TTL NW | V18: TTL GW | W18: CARTON SIZE ( CM)
A19: 1 | C19: 2 | E19: NESSB711 | F19: 001 BLACK | G19: 001 | H19: 36 | J19: 36 | Q19: 2 | R19: 72 | S19: =+U19/Q19 -> 3.32 | T19: =+V19/Q19 -> 4.32 | U19: 6.64 | V19: 8.64 | W19: =AA19&"*"&AB19&"*"&AC19 -> 50.8*43.18*11.43 | X19: 20 | Y19: 17 | Z19: 4.5 | AA19: =+X19*2.54 -> 50.8 | AB19: =+Y19*2.54 -> 43.18 | AC19: =+Z19*2.54 -> 11.43
A20: 3 | C20: 6 | H20: 36 | K20: 36 | Q20: 4 | R20: 144 | S20: =+U20/Q20 -> 3.64 | T20: =+V20/Q20 -> 4.64 | U20: 14.56 | V20: 18.56 | W20: =AA20&"*"&AB20&"*"&AC20 -> 50.8*43.18*11.43 | X20: 20 | Y20: 17 | Z20: 4.5 | AA20: =+X20*2.54 -> 50.8 | AB20: =+Y20*2.54 -> 43.18 | AC20: =+Z20*2.54 -> 11.43
A21: 7 | C21: 10 | H21: 36 | L21: 36 | Q21: 4 | R21: 144 | S21: =+U21/Q21 -> 3.93 | T21: =+V21/Q21 -> 4.96 | U21: 15.72 | V21: 19.84 | W21: =AA21&"*"&AB21&"*"&AC21 -> 50.8*43.18*12.7 | X21: 20 | Y21: 17 | Z21: 5 | AA21: =+X21*2.54 -> 50.8 | AB21: =+Y21*2.54 -> 43.18 | AC21: =+Z21*2.54 -> 12.7
A22: 11 | C22: 12 | H22: 36 | M22: 36 | Q22: 2 | R22: 72 | S22: =+U22/Q22 -> 4.25 | T22: =+V22/Q22 -> 5.28 | U22: 8.5 | V22: 10.56 | W22: =AA22&"*"&AB22&"*"&AC22 -> 50.8*43.18*12.7 | X22: 20 | Y22: 17 | Z22: 5 | AA22: =+X22*2.54 -> 50.8 | AB22: =+Y22*2.54 -> 43.18 | AC22: =+Z22*2.54 -> 12.7
A23: 13 | C23: 13 | D23: ODD CARTON | H23: 28 | J23: 28 | Q23: 1 | R23: 28 | S23: =+U23/Q23 -> 2.36 | T23: =+V23/Q23 -> 3.36 | U23: 2.36 | V23: 3.36 | W23: =AA23&"*"&AB23&"*"&AC23 -> 50.8*43.18*10.16 | X23: 20 | Y23: 17 | Z23: 4 | AA23: =+X23*2.54 -> 50.8 | AB23: =+Y23*2.54 -> 43.18 | AC23: =+Z23*2.54 -> 10.16
A24: 14 | C24: 14 | D24: ODD CARTON | H24: 28 | M24: 28 | Q24: 1 | R24: 28 | S24: =+U24/Q24 -> 3.1 | T24: =+V24/Q24 -> 4.1 | U24: 3.1 | V24: 4.1 | W24: =AA24&"*"&AB24&"*"&AC24 -> 50.8*43.18*11.43 | X24: 20 | Y24: 17 | Z24: 4.5 | AA24: =+X24*2.54 -> 50.8 | AB24: =+Y24*2.54 -> 43.18 | AC24: =+Z24*2.54 -> 11.43
A25: Master box 15-16 | D25: Master box | X25: 19 | Y25: 11 | Z25: 4.5 | AA25: =+X25*2.54 -> 48.26 | AB25: =+Y25*2.54 -> 27.94 | AC25: =+Z25*2.54 -> 11.43
A26: 15 | C26: 15 | D26: Small box | H26: 6 | K26: 6 | Q26: 1 | R26: 6 | S26: =+U26/Q26 -> 1.75 | T26: =+V26/Q26 -> 2.22 | U26: 1.75 | V26: 2.22 | W26: =AA26&"*"&AB26&"*"&AC26 -> 25.4*22.86*8.89 | X26: 10 | Y26: 9 | Z26: 3.5 | AA26: =+X26*2.54 -> 25.4 | AB26: =+Y26*2.54 -> 22.86 | AC26: =+Z26*2.54 -> 8.89
A27: 16 | C27: 16 | D27: Small box | H27: 6 | L27: 6 | Q27: 1 | R27: 6 | W27: =AA27&"*"&AB27&"*"&AC27 -> 25.4*22.86*8.89 | X27: 10 | Y27: 9 | Z27: 3.5 | AA27: =+X27*2.54 -> 25.4 | AB27: =+Y27*2.54 -> 22.86 | AC27: =+Z27*2.54 -> 8.89
M28: 100
A29: 17 | C29: 17 | E29: NESSB711 | F29: 655 DESERT PINK | G29: 655 | H29: 36 | J29: 36 | Q29: 1 | R29: 36 | S29: =+U29/Q29 -> 3.32 | T29: =+V29/Q29 -> 4.32 | U29: 3.32 | V29: 4.32 | W29: =AA29&"*"&AB29&"*"&AC29 -> 50.8*43.18*11.43 | X29: 20 | Y29: 17 | Z29: 4.5 | AA29: =+X29*2.54 -> 50.8 | AB29: =+Y29*2.54 -> 43.18 | AC29: =+Z29*2.54 -> 11.43
A30: 18 | C30: 18 | H30: 36 | K30: 36 | Q30: 1 | R30: 36 | S30: =+U30/Q30 -> 3.64 | T30: =+V30/Q30 -> 4.64 | U30: 3.64 | V30: 4.64 | W30: =AA30&"*"&AB30&"*"&AC30 -> 50.8*43.18*11.43 | X30: 20 | Y30: 17 | Z30: 4.5 | AA30: =+X30*2.54 -> 50.8 | AB30: =+Y30*2.54 -> 43.18 | AC30: =+Z30*2.54 -> 11.43
A31: 19 | C31: 19 | H31: 39 | K31: 39 | Q31: 1 | R31: 39 | S31: =+U31/Q31 -> 1.84 | T31: =+V31/Q31 -> 4.84 | U31: 1.84 | V31: 4.84 | W31: =AA31&"*"&AB31&"*"&AC31 -> 50.8*43.18*12.7 | X31: 20 | Y31: 17 | Z31: 5 | AA31: =+X31*2.54 -> 50.8 | AB31: =+Y31*2.54 -> 43.18 | AC31: =+Z31*2.54 -> 12.7
A32: 20 | C32: 20 | H32: 36 | L32: 36 | Q32: 1 | R32: 36 | S32: =+U32/Q32 -> 3.96 | T32: =+V32/Q32 -> 4.96 | U32: 3.96 | V32: 4.96 | W32: =AA32&"*"&AB32&"*"&AC32 -> 50.8*43.18*11.43 | X32: 20 | Y32: 17 | Z32: 4.5 | AA32: =+X32*2.54 -> 50.8 | AB32: =+Y32*2.54 -> 43.18 | AC32: =+Z32*2.54 -> 11.43
A33: 21 | C33: 21 | H33: 39 | L33: 39 | Q33: 1 | R33: 39 | S33: =+U33/Q33 -> 2.02 | T33: =+V33/Q33 -> 5.02 | U33: 2.02 | V33: 5.02 | W33: =AA33&"*"&AB33&"*"&AC33 -> 50.8*43.18*12.7 | X33: 20 | Y33: 17 | Z33: 5 | AA33: =+X33*2.54 -> 50.8 | AB33: =+Y33*2.54 -> 43.18 | AC33: =+Z33*2.54 -> 12.7
A34: 22 | C34: 22 | H34: 36 | M34: 36 | Q34: 1 | R34: 36 | S34: =+U34/Q34 -> 2.28 | T34: =+V34/Q34 -> 5.28 | U34: 2.28 | V34: 5.28 | W34: =AA34&"*"&AB34&"*"&AC34 -> 50.8*43.18*12.7 | X34: 20 | Y34: 17 | Z34: 5 | AA34: =+X34*2.54 -> 50.8 | AB34: =+Y34*2.54 -> 43.18 | AC34: =+Z34*2.54 -> 12.7
A35: 23 | C35: 23 | D35: ODD CARTON | H35: 14 | J35: 14 | Q35: 1 | R35: 14 | S35: =+U35/Q35 -> 1.24 | T35: =+V35/Q35 -> 1.68 | U35: 1.24 | V35: 1.68 | W35: =AA35&"*"&AB35&"*"&AC35 -> 44.45*25.4*7.62 | X35: 17.5 | Y35: 10 | Z35: 3 | AA35: =+X35*2.54 -> 44.45 | AB35: =+Y35*2.54 -> 25.4 | AC35: =+Z35*2.54 -> 7.62
A36: 24 | C36: 24 | D36: ODD CARTON | H36: 14 | M36: 14 | Q36: 1 | R36: 14 | S36: =+U36/Q36 -> 1.61 | T36: =+V36/Q36 -> 2.05 | U36: 1.61 | V36: 2.05 | W36: =AA36&"*"&AB36&"*"&AC36 -> 44.45*25.4*7.62 | X36: 17.5 | Y36: 10 | Z36: 3 | AA36: =+X36*2.54 -> 44.45 | AB36: =+Y36*2.54 -> 25.4 | AC36: =+Z36*2.54 -> 7.62
M37: 50
M39: =SUM(M19:M38) -> 264 | N39: =SUM(N19:N38) -> 0 | O39: =SUM(O19:O38) -> 0 | P39: =SUM(P19:P38) -> 0 | Q39: =SUM(Q19:Q38) -> 24 | R39: =SUM(R19:R38) -> 750 | U39: =SUM(U19:U38) -> 72.54 | V39: =SUM(V19:V38) -> 100.07
D42: CUSTOMER PO | E42: Style | F42: Color | G42: Color Code | H42: xs | I42: S | J42: M | K42: L | L42: XL | Q42: TOT CTNS | R42: TOT PCS
D43: DV10 | E43: NESSB711 | F43: BLACK | G43: 001 | I43: 100 | J43: 150 | K43: 150 | L43: 100 | Q43: 16 | R43: 500 | X43: =+SUM(H43:L43) -> 500 | Y43: =+R43-X43 -> 0
D44: DV10 | E44: NESSB711 | F44: DESERT PINK | G44: 655 | I44: 50 | J44: 75 | K44: 75 | L44: 50 | Q44: 8 | R44: 250 | X44: =+SUM(H44:L44) -> 250 | Y44: =+R44-X44 -> 0
K46: TOTAL | Q46: =SUM(Q43:Q44) -> 24 | R46: =SUM(R43:R44) -> 750

Sheet SOLID PL DV6
A4: PACKING LIST
H5: PEI
A6: ISSUE TO : | E6: =+'[1]INVOICE 11'!C7 -> SUPREME INTERNATIONAL, LLC | H6: STYLE:
H7: LABEL
H8: P.O.:
H9: PCS
H10: SIZES
A12: PAYMENT: T/C | H12: MADE IN
A13: PO NO: | B13: DV6 | H13: C# UP
A14: CUSTOMER PO.: | E14: =+B13 -> DV6
A15: INVOICE NO: | D15: =+'INVOICE 94'!M2 -> 7726477
A16: Detail Breakdown
A18: CASE FROM-TO | D18: REMARKS | E18: Style | F18: Color Name | G18: Color code | H18: Units/case | I18: xs | J18: S | K18: M | L18: L | M18: 4 | N18: 5 | O18: 6 | P18: 6X | Q18: TOT CTNS | R18: TOT PCS | S18: NW | T18: GW | U18: TTL NW | V18: TTL GW | W18: CARTON SIZE ( CM)
A19: 1 | C19: 5 | E19: NESSB711 | F19: 001 BLACK | G19: 001 | H19: 36 | J19: 36 | Q19: 5 | R19: 180 | S19: =+U19/Q19 -> 3.32 | T19: =+V19/Q19 -> 4.32 | U19: 16.6 | V19: 21.6 | W19: =AA19&"*"&AB19&"*"&AC19 -> 50.8*43.18*11.43 | X19: 20 | Y19: 17 | Z19: 4.5 | AA19: =+X19*2.54 -> 50.8 | AB19: =+Y19*2.54 -> 43.18 | AC19: =+Z19*2.54 -> 11.43
A20: 6 | C20: 13 | H20: 36 | K20: 36 | Q20: 8 | R20: 288 | S20: =+U20/Q20 -> 3.64 | T20: =+V20/Q20 -> 4.64 | U20: 29.12 | V20: 37.12 | W20: =AA20&"*"&AB20&"*"&AC20 -> 50.8*43.18*11.43 | X20: 20 | Y20: 17 | Z20: 4.5 | AA20: =+X20*2.54 -> 50.8 | AB20: =+Y20*2.54 -> 43.18 | AC20: =+Z20*2.54 -> 11.43
A21: 14 | C21: 21 | H21: 36 | L21: 36 | Q21: 8 | R21: 288 | S21: =+U21/Q21 -> 3.93 | T21: =+V21/Q21 -> 4.96 | U21: 31.44 | V21: 39.68 | W21: =AA21&"*"&AB21&"*"&AC21 -> 50.8*43.18*12.7 | X21: 20 | Y21: 17 | Z21: 5 | AA21: =+X21*2.54 -> 50.8 | AB21: =+Y21*2.54 -> 43.18 | AC21: =+Z21*2.54 -> 12.7
A22: 22 | C22: 26 | H22: 36 | M22: 36 | Q22: 5 | R22: 180 | S22: =+U22/Q22 -> 4.25 | T22: =+V22/Q22 -> 5.28 | U22: 21.25 | V22: 26.4 | W22: =AA22&"*"&AB22&"*"&AC22 -> 50.8*43.18*12.7 | X22: 20 | Y22: 17 | Z22: 5 | AA22: =+X22*2.54 -> 50.8 | AB22: =+Y22*2.54 -> 43.18 | AC22: =+Z22*2.54 -> 12.7
A23: 27 | C23: 27 | D23: ODD CARTON | H23: 18 | J23: 18 | Q23: 1 | R23: 18 | S23: =+U23/Q23 -> 1.66 | T23: =+V23/Q23 -> 2.23 | U23: 1.66 | V23: 2.23 | W23: =AA23&"*"&AB23&"*"&AC23 -> 50.8*43.18*7.62 | X23: 20 | Y23: 17 | Z23: 3 | AA23: =+X23*2.54 -> 50.8 | AB23: =+Y23*2.54 -> 43.18 | AC23: =+Z23*2.54 -> 7.62
A24: 28 | C24: 28 | D24: ODD CARTON | H24: 9 | K24: 9 | Q24: 1 | R24: 9 | S24: =+U24/Q24 -> 0.91 | T24: =+V24/Q24 -> 1.66 | U24: 0.91 | V24: 1.66 | W24: =AA24&"*"&AB24&"*"&AC24 -> 44.45*25.4*7.62 | X24: 17.5 | Y24: 10 | Z24: 3 | AA24: =+X24*2.54 -> 44.45 | AB24: =+Y24*2.54 -> 25.4 | AC24: =+Z24*2.54 -> 7.62
A25: 29 | C25: 29 | D25: ODD CARTON | H25: 9 | L25: 9 | Q25: 1 | R25: 9 | S25: =+U25/Q25 -> 0.98 | T25: =+V25/Q25 -> 1.72 | U25: 0.98 | V25: 1.72 | W25: =AA25&"*"&AB25&"*"&AC25 -> 44.45*25.4*7.62 | X25: 17.5 | Y25: 10 | Z25: 3 | AA25: =+X25*2.54 -> 44.45 | AB25: =+Y25*2.54 -> 25.4 | AC25: =+Z25*2.54 -> 7.62
A26: 30 | C26: 30 | D26: ODD CARTON | H26: 18 | M26: 18 | Q26: 1 | R26: 18 | S26: =+U26/Q26 -> 2.12 | T26: =+V26/Q26 -> 3.04 | U26: 2.12 | V26: 3.04 | W26: =AA26&"*"&AB26&"*"&AC26 -> 50.8*43.18*7.62 | X26: 20 | Y26: 17 | Z26: 3 | AA26: =+X26*2.54 -> 50.8 | AB26: =+Y26*2.54 -> 43.18 | AC26: =+Z26*2.54 -> 7.62
M27: 198 | AA27: =+X27*2.54 -> 0 | AB27: =+Y27*2.54 -> 0 | AC27: =+Z27*2.54 -> 0
A28: 31 | C28: 32 | E28: NESSB711 | F28: 655 DESERT PINK | G28: 655 | H28: 36 | J28: 36 | Q28: 2 | R28: 72 | S28: =+U28/Q28 -> 3.32 | T28: =+V28/Q28 -> 4.32 | U28: 6.64 | V28: 8.64 | W28: =AA28&"*"&AB28&"*"&AC28 -> 50.8*43.18*11.43 | X28: 20 | Y28: 17 | Z28: 4.5 | AA28: =+X28*2.54 -> 50.8 | AB28: =+Y28*2.54 -> 43.18 | AC28: =+Z28*2.54 -> 11.43
A29: 33 | C29: 36 | H29: 36 | K29: 36 | Q29: 4 | R29: 144 | S29: =+U29/Q29 -> 3.64 | T29: =+V29/Q29 -> 4.64 | U29: 14.56 | V29: 18.56 | W29: =AA29&"*"&AB29&"*"&AC29 -> 50.8*43.18*11.43 | X29: 20 | Y29: 17 | Z29: 4.5 | AA29: =+X29*2.54 -> 50.8 | AB29: =+Y29*2.54 -> 43.18 | AC29: =+Z29*2.54 -> 11.43
A30: 37 | C30: 40 | H30: 36 | L30: 36 | Q30: 4 | R30: 144 | S30: =+U30/Q30 -> 3.93 | T30: =+V30/Q30 -> 4.96 | U30: 15.72 | V30: 19.84 | W30: =AA30&"*"&AB30&"*"&AC30 -> 50.8*43.18*12.7 | X30: 20 | Y30: 17 | Z30: 5 | AA30: =+X30*2.54 -> 50.8 | AB30: =+Y30*2.54 -> 43.18 | AC30: =+Z30*2.54 -> 12.7
A31: 41 | C31: 42 | H31: 36 | M31: 36 | Q31: 2 | R31: 72 | S31: =+U31/Q31 -> 4.25 | T31: =+V31/Q31 -> 5.28 | U31: 8.5 | V31: 10.56 | W31: =AA31&"*"&AB31&"*"&AC31 -> 50.8*43.18*12.7 | X31: 20 | Y31: 17 | Z31: 5 | AA31: =+X31*2.54 -> 50.8 | AB31: =+Y31*2.54 -> 43.18 | AC31: =+Z31*2.54 -> 12.7
A32: 43 | C32: 43 | D32: ODD CARTON | H32: 28 | J32: 28 | Q32: 1 | R32: 28 | S32: =+U32/Q32 -> 2.58 | T32: =+V32/Q32 -> 3.55 | U32: 2.58 | V32: 3.55 | W32: =AA32&"*"&AB32&"*"&AC32 -> 50.8*43.18*10.16 | X32: 20 | Y32: 17 | Z32: 4 | AA32: =+X32*2.54 -> 50.8 | AB32: =+Y32*2.54 -> 43.18 | AC32: =+Z32*2.54 -> 10.16
A33: 44 | C33: 44 | D33: ODD CARTON | H33: 28 | M33: 28 | Q33: 1 | R33: 28 | S33: =+U33/Q33 -> 3.3 | T33: =+V33/Q33 -> 4.12 | U33: 3.3 | V33: 4.12 | W33: =AA33&"*"&AB33&"*"&AC33 -> 50.8*43.18*11.43 | X33: 20 | Y33: 17 | Z33: 4.5 | AA33: =+X33*2.54 -> 50.8 | AB33: =+Y33*2.54 -> 43.18 | AC33: =+Z33*2.54 -> 11.43
A34: Master box 45-46 | D34: Master box | X34: 19 | Y34: 11 | Z34: 4.5 | AA34: =+X34*2.54 -> 48.26 | AB34: =+Y34*2.54 -> 27.94 | AC34: =+Z34*2.54 -> 11.43
A35: 45 | C35: 45 | D35: Small box | H35: 6 | K35: 6 | Q35: 1 | R35: 6 | S35: =+U35/Q35 -> 1.12 | T35: =+V35/Q35 -> 2.04 | U35: 1.12 | V35: 2.04 | W35: =AA35&"*"&AB35&"*"&AC35 -> 25.4*22.86*8.89 | X35: 10 | Y35: 9 | Z35: 3.5 | AA35: =+X35*2.54 -> 25.4 | AB35: =+Y35*2.54 -> 22.86 | AC35: =+Z35*2.54 -> 8.89
A36: 46 | C36: 46 | D36: Small box | H36: 6 | L36: 6 | R36: 6 | W36: =AA36&"*"&AB36&"*"&AC36 -> 25.4*22.86*8.89 | X36: 10 | Y36: 9 | Z36: 3.5 | AA36: =+X36*2.54 -> 25.4 | AB36: =+Y36*2.54 -> 22.86 | AC36: =+Z36*2.54 -> 8.89
M37: 50
M39: =SUM(M19:M38) -> 366 | N39: =SUM(N19:N38) -> 0 | O39: =SUM(O19:O38) -> 0 | P39: =SUM(P19:P38) -> 0 | Q39: =SUM(Q19:Q38) -> 45 | R39: =SUM(R19:R38) -> 1490 | U39: =SUM(U19:U38) -> 156.5 | V39: =SUM(V19:V38) -> 200.76
D42: CUSTOMER PO | E42: Style | F42: Color | G42: Color Code | H42: xs | I42: S | J42: M | K42: L | L42: XL | Q42: TOT CTNS | R42: TOT PCS
D43: DV6 | E43: NESSB711 | F43: BLACK | G43: 001 | I43: 198 | J43: 297 | K43: 297 | L43: 198 | Q43: 30 | R43: 990 | X43: =+SUM(H43:L43) -> 990 | Y43: =+R43-X43 -> 0
D44: DV6 | E44: NESSB711 | F44: DESERT PINK | G44: 655 | I44: 100 | J44: 150 | K44: 150 | L44: 100 | Q44: 15 | R44: 500 | X44: =+SUM(H44:L44) -> 500 | Y44: =+R44-X44 -> 0
K46: TOTAL | Q46: =SUM(Q43:Q44) -> 45 | R46: =SUM(R43:R44) -> 1490

Sheet IRREGULAR SS PL DV6
A4: PACKING LIST
H5: PEI
A6: ISSUE TO : | E6: =+'[1]INVOICE 11'!C7 -> SUPREME INTERNATIONAL, LLC | H6: STYLE:
H7: LABEL
H8: P.O.:
H9: PCS
H10: SIZES
A12: PAYMENT: T/C | H12: MADE IN
A13: PO NO: | B13: DV6 | H13: C# UP
A14: CUSTOMER PO.: | E14: =+B13 -> DV6
A15: INVOICE NO: | D15: =+'INVOICE 94'!M2 -> 7726477
A16: Detail Breakdown
A18: CASE FROM-TO | D18: REMARKS | E18: Style | F18: Color Name | G18: Color code | H18: Units/case | I18: xs | J18: S | K18: M | L18: L | M18: 4 | N18: 5 | O18: 6 | P18: 6X | Q18: TOT CTNS | R18: TOT PCS | S18: NW | T18: GW | U18: TTL NW | V18: TTL GW | W18: CARTON SIZE ( CM)
A19: 1 | C19: 5 | E19: NESSB711 | F19: 001 BLACK | G19: 001 | H19: 36 | J19: 36 | Q19: 5 | R19: 180 | S19: =+U19/Q19 -> 3.32 | T19: =+V19/Q19 -> 4.32 | U19: 16.6 | V19: 21.6 | W19: =AA19&"*"&AB19&"*"&AC19 -> 50.8*43.18*11.43 | X19: 20 | Y19: 17 | Z19: 4.5 | AA19: =+X19*2.54 -> 50.8 | AB19: =+Y19*2.54 -> 43.18 | AC19: =+Z19*2.54 -> 11.43
A20: 6 | C20: 13 | H20: 36 | K20: 36 | Q20: 8 | R20: 288 | S20: =+U20/Q20 -> 3.64 | T20: =+V20/Q20 -> 4.64 | U20: 29.12 | V20: 37.12 | W20: =AA20&"*"&AB20&"*"&AC20 -> 50.8*43.18*11.43 | X20: 20 | Y20: 17 | Z20: 4.5 | AA20: =+X20*2.54 -> 50.8 | AB20: =+Y20*2.54 -> 43.18 | AC20: =+Z20*2.54 -> 11.43
A21: 14 | C21: 21 | H21: 36 | L21: 36 | Q21: 8 | R21: 288 | S21: =+U21/Q21 -> 3.93 | T21: =+V21/Q21 -> 4.96 | U21: 31.44 | V21: 39.68 | W21: =AA21&"*"&AB21&"*"&AC21 -> 50.8*43.18*12.7 | X21: 20 | Y21: 17 | Z21: 5 | AA21: =+X21*2.54 -> 50.8 | AB21: =+Y21*2.54 -> 43.18 | AC21: =+Z21*2.54 -> 12.7
A22: 22 | C22: 26 | H22: 36 | M22: 36 | Q22: 5 | R22: 180 | S22: =+U22/Q22 -> 4.25 | T22: =+V22/Q22 -> 5.28 | U22: 21.25 | V22: 26.4 | W22: =AA22&"*"&AB22&"*"&AC22 -> 50.8*43.18*12.7 | X22: 20 | Y22: 17 | Z22: 5 | AA22: =+X22*2.54 -> 50.8 | AB22: =+Y22*2.54 -> 43.18 | AC22: =+Z22*2.54 -> 12.7
A23: 27 | C23: 27 | D23: ODD CARTON | H23: 18 | J23: 18 | Q23: 1 | R23: 18 | S23: =+U23/Q23 -> 1.66 | T23: =+V23/Q23 -> 2.23 | U23: 1.66 | V23: 2.23 | W23: =AA23&"*"&AB23&"*"&AC23 -> 50.8*43.18*7.62 | X23: 20 | Y23: 17 | Z23: 3 | AA23: =+X23*2.54 -> 50.8 | AB23: =+Y23*2.54 -> 43.18 | AC23: =+Z23*2.54 -> 7.62
A24: 28 | C24: 28 | D24: ODD CARTON | H24: 9 | K24: 9 | Q24: 1 | R24: 9 | S24: =+U24/Q24 -> 0.91 | T24: =+V24/Q24 -> 1.66 | U24: 0.91 | V24: 1.66 | W24: =AA24&"*"&AB24&"*"&AC24 -> 44.45*25.4*7.62 | X24: 17.5 | Y24: 10 | Z24: 3 | AA24: =+X24*2.54 -> 44.45 | AB24: =+Y24*2.54 -> 25.4 | AC24: =+Z24*2.54 -> 7.62
A25: 29 | C25: 29 | D25: ODD CARTON | H25: 9 | L25: 9 | Q25: 1 | R25: 9 | S25: =+U25/Q25 -> 0.98 | T25: =+V25/Q25 -> 1.72 | U25: 0.98 | V25: 1.72 | W25: =AA25&"*"&AB25&"*"&AC25 -> 44.45*25.4*7.62 | X25: 17.5 | Y25: 10 | Z25: 3 | AA25: =+X25*2.54 -> 44.45 | AB25: =+Y25*2.54 -> 25.4 | AC25: =+Z25*2.54 -> 7.62
A26: 30 | C26: 30 | D26: ODD CARTON | H26: 18 | M26: 18 | Q26: 1 | R26: 18 | S26: =+U26/Q26 -> 2.12 | T26: =+V26/Q26 -> 3.04 | U26: 2.12 | V26: 3.04 | W26: =AA26&"*"&AB26&"*"&AC26 -> 50.8*43.18*7.62 | X26: 20 | Y26: 17 | Z26: 3 | AA26: =+X26*2.54 -> 50.8 | AB26: =+Y26*2.54 -> 43.18 | AC26: =+Z26*2.54 -> 7.62
M27: 198 | AA27: =+X27*2.54 -> 0 | AB27: =+Y27*2.54 -> 0 | AC27: =+Z27*2.54 -> 0
A28: 31 | C28: 32 | E28: NESSB711 | F28: 655 DESERT PINK | G28: 655 | H28: 36 | J28: 36 | Q28: 2 | R28: 72 | S28: =+U28/Q28 -> 3.32 | T28: =+V28/Q28 -> 4.32 | U28: 6.64 | V28: 8.64 | W28: =AA28&"*"&AB28&"*"&AC28 -> 50.8*43.18*11.43 | X28: 20 | Y28: 17 | Z28: 4.5 | AA28: =+X28*2.54 -> 50.8 | AB28: =+Y28*2.54 -> 43.18 | AC28: =+Z28*2.54 -> 11.43
A29: 33 | C29: 36 | H29: 36 | K29: 36 | Q29: 4 | R29: 144 | S29: =+U29/Q29 -> 3.64 | T29: =+V29/Q29 -> 4.64 | U29: 14.56 | V29: 18.56 | W29: =AA29&"*"&AB29&"*"&AC29 -> 50.8*43.18*11.43 | X29: 20 | Y29: 17 | Z29: 4.5 | AA29: =+X29*2.54 -> 50.8 | AB29: =+Y29*2.54 -> 43.18 | AC29: =+Z29*2.54 -> 11.43
A30: 37 | C30: 40 | H30: 36 | L30: 36 | Q30: 4 | R30: 144 | S30: =+U30/Q30 -> 3.93 | T30: =+V30/Q30 -> 4.96 | U30: 15.72 | V30: 19.84 | W30: =AA30&"*"&AB30&"*"&AC30 -> 50.8*43.18*12.7 | X30: 20 | Y30: 17 | Z30: 5 | AA30: =+X30*2.54 -> 50.8 | AB30: =+Y30*2.54 -> 43.18 | AC30: =+Z30*2.54 -> 12.7
A31: 41 | C31: 42 | H31: 36 | M31: 36 | Q31: 2 | R31: 72 | S31: =+U31/Q31 -> 4.25 | T31: =+V31/Q31 -> 5.28 | U31: 8.5 | V31: 10.56 | W31: =AA31&"*"&AB31&"*"&AC31 -> 50.8*43.18*12.7 | X31: 20 | Y31: 17 | Z31: 5 | AA31: =+X31*2.54 -> 50.8 | AB31: =+Y31*2.54 -> 43.18 | AC31: =+Z31*2.54 -> 12.7
A32: 43 | C32: 43 | D32: ODD CARTON | H32: 28 | J32: 28 | Q32: 1 | R32: 28 | S32: =+U32/Q32 -> 2.58 | T32: =+V32/Q32 -> 3.55 | U32: 2.58 | V32: 3.55 | W32: =AA32&"*"&AB32&"*"&AC32 -> 50.8*43.18*10.16 | X32: 20 | Y32: 17 | Z32: 4 | AA32: =+X32*2.54 -> 50.8 | AB32: =+Y32*2.54 -> 43.18 | AC32: =+Z32*2.54 -> 10.16
A33: 44 | C33: 44 | D33: ODD CARTON | H33: 28 | M33: 28 | Q33: 1 | R33: 28 | S33: =+U33/Q33 -> 3.3 | T33: =+V33/Q33 -> 4.12 | U33: 3.3 | V33: 4.12 | W33: =AA33&"*"&AB33&"*"&AC33 -> 50.8*43.18*11.43 | X33: 20 | Y33: 17 | Z33: 4.5 | AA33: =+X33*2.54 -> 50.8 | AB33: =+Y33*2.54 -> 43.18 | AC33: =+Z33*2.54 -> 11.43
A34: Master box 45-46 | D34: Master box | X34: 19 | Y34: 11 | Z34: 4.5 | AA34: =+X34*2.54 -> 48.26 | AB34: =+Y34*2.54 -> 27.94 | AC34: =+Z34*2.54 -> 11.43
A35: 45 | C35: 45 | D35: Small box | H35: 6 | K35: 6 | Q35: 1 | R35: 6 | S35: =+U35/Q35 -> 1.12 | T35: =+V35/Q35 -> 2.04 | U35: 1.12 | V35: 2.04 | W35: =AA35&"*"&AB35&"*"&AC35 -> 25.4*22.86*8.89 | X35: 10 | Y35: 9 | Z35: 3.5 | AA35: =+X35*2.54 -> 25.4 | AB35: =+Y35*2.54 -> 22.86 | AC35: =+Z35*2.54 -> 8.89
A36: 46 | C36: 46 | D36: Small box | H36: 6 | L36: 6 | Q36: 1 | R36: 6 | W36: =AA36&"*"&AB36&"*"&AC36 -> 25.4*22.86*8.89 | X36: 10 | Y36: 9 | Z36: 3.5 | AA36: =+X36*2.54 -> 25.4 | AB36: =+Y36*2.54 -> 22.86 | AC36: =+Z36*2.54 -> 8.89
M37: 50
M39: =SUM(M19:M38) -> 366 | N39: =SUM(N19:N38) -> 0 | O39: =SUM(O19:O38) -> 0 | P39: =SUM(P19:P38) -> 0 | Q39: =SUM(Q19:Q38) -> 46 | R39: =SUM(R19:R38) -> 1490 | U39: =SUM(U19:U38) -> 156.5 | V39: =SUM(V19:V38) -> 200.76
D42: CUSTOMER PO | E42: Style | F42: Color | G42: Color Code | H42: xs | I42: S | J42: M | K42: L | L42: XL | Q42: TOT CTNS | R42: TOT PCS
D43: DV6 | E43: NESSB711 | F43: BLACK | G43: 001 | I43: 198 | J43: 297 | K43: 297 | L43: 198 | Q43: 30 | R43: 990 | X43: =+SUM(H43:L43) -> 990 | Y43: =+R43-X43 -> 0
D44: DV6 | E44: NESSB711 | F44: DESERT PINK | G44: 655 | I44: 100 | J44: 150 | K44: 150 | L44: 100 | Q44: 16 | R44: 500 | X44: =+SUM(H44:L44) -> 500 | Y44: =+R44-X44 -> 0
K46: TOTAL | Q46: =SUM(Q43:Q44) -> 46 | R46: =SUM(R43:R44) -> 1490

Sheet SOLID PL DV7
A4: PACKING LIST
H5: PEI
A6: ISSUE TO : | E6: =+'[1]INVOICE 11'!C7 -> SUPREME INTERNATIONAL, LLC | H6: STYLE:
H7: LABEL
H8: P.O.:
H9: PCS
H10: SIZES
A12: PAYMENT: T/C | H12: MADE IN
A13: PO NO: | B13: DV7 | H13: C# UP
A14: CUSTOMER PO.: | E14: =+B13 -> DV7
A15: INVOICE NO: | D15: =+'INVOICE 94'!M2 -> 7726477
A16: Detail Breakdown
A18: CASE FROM-TO | D18: REMARKS | E18: Style | F18: Color Name | G18: Color code | H18: Units/case | I18: xs | J18: S | K18: M | L18: L | M18: 4 | N18: 5 | O18: 6 | P18: 6X | Q18: TOT CTNS | R18: TOT PCS | S18: NW | T18: GW | U18: TTL NW | V18: TTL GW | W18: CARTON SIZE ( CM)
A19: 1 | C19: 2 | E19: NESSB711 | F19: 001 BLACK | G19: 001 | H19: 36 | J19: 36 | Q19: 2 | R19: 72 | S19: =+U19/Q19 -> 3.32 | T19: =+V19/Q19 -> 4.32 | U19: 6.64 | V19: 8.64 | W19: =AA19&"*"&AB19&"*"&AC19 -> 50.8*43.18*11.43 | X19: 20 | Y19: 17 | Z19: 4.5 | AA19: =+X19*2.54 -> 50.8 | AB19: =+Y19*2.54 -> 43.18 | AC19: =+Z19*2.54 -> 11.43
A20: 3 | C20: 6 | H20: 36 | K20: 36 | Q20: 4 | R20: 144 | S20: =+U20/Q20 -> 3.64 | T20: =+V20/Q20 -> 4.64 | U20: 14.56 | V20: 18.56 | W20: =AA20&"*"&AB20&"*"&AC20 -> 50.8*43.18*11.43 | X20: 20 | Y20: 17 | Z20: 4.5 | AA20: =+X20*2.54 -> 50.8 | AB20: =+Y20*2.54 -> 43.18 | AC20: =+Z20*2.54 -> 11.43
A21: 7 | C21: 10 | H21: 36 | L21: 36 | Q21: 4 | R21: 144 | S21: =+U21/Q21 -> 3.93 | T21: =+V21/Q21 -> 4.96 | U21: 15.72 | V21: 19.84 | W21: =AA21&"*"&AB21&"*"&AC21 -> 50.8*43.18*12.7 | X21: 20 | Y21: 17 | Z21: 5 | AA21: =+X21*2.54 -> 50.8 | AB21: =+Y21*2.54 -> 43.18 | AC21: =+Z21*2.54 -> 12.7
A22: 11 | C22: 12 | H22: 36 | M22: 36 | Q22: 2 | R22: 72 | S22: =+U22/Q22 -> 4.25 | T22: =+V22/Q22 -> 5.28 | U22: 8.5 | V22: 10.56 | W22: =AA22&"*"&AB22&"*"&AC22 -> 50.8*43.18*12.7 | X22: 20 | Y22: 17 | Z22: 5 | AA22: =+X22*2.54 -> 50.8 | AB22: =+Y22*2.54 -> 43.18 | AC22: =+Z22*2.54 -> 12.7
A23: 13 | C23: 13 | D23: ODD CARTON | H23: 28 | J23: 28 | Q23: 1 | R23: 28 | S23: =+U23/Q23 -> 2.58 | T23: =+V23/Q23 -> 3.48 | U23: 2.58 | V23: 3.48 | W23: =AA23&"*"&AB23&"*"&AC23 -> 50.8*43.18*10.16 | X23: 20 | Y23: 17 | Z23: 4 | AA23: =+X23*2.54 -> 50.8 | AB23: =+Y23*2.54 -> 43.18 | AC23: =+Z23*2.54 -> 10.16
A24: 14 | C24: 14 | D24: ODD CARTON | H24: 28 | M24: 28 | Q24: 1 | R24: 28 | S24: =+U24/Q24 -> 3.3 | T24: =+V24/Q24 -> 4.27 | U24: 3.3 | V24: 4.27 | W24: =AA24&"*"&AB24&"*"&AC24 -> 50.8*43.18*11.43 | X24: 20 | Y24: 17 | Z24: 4.5 | AA24: =+X24*2.54 -> 50.8 | AB24: =+Y24*2.54 -> 43.18 | AC24: =+Z24*2.54 -> 11.43
A25: Master box 15-16 | D25: Master box | W25: =AA25&"*"&AB25&"*"&AC25 -> 48.26*27.94*11.43 | X25: 19 | Y25: 11 | Z25: 4.5 | AA25: =+X25*2.54 -> 48.26 | AB25: =+Y25*2.54 -> 27.94 | AC25: =+Z25*2.54 -> 11.43
A26: 15 | C26: 15 | D26: Small box | H26: 6 | K26: 6 | Q26: 1 | R26: 6 | S26: =+U26/Q26 -> 1.28 | T26: =+V26/Q26 -> 2.14 | U26: 1.28 | V26: 2.14 | W26: =AA26&"*"&AB26&"*"&AC26 -> 25.4*22.86*8.89 | X26: 10 | Y26: 9 | Z26: 3.5 | AA26: =+X26*2.54 -> 25.4 | AB26: =+Y26*2.54 -> 22.86 | AC26: =+Z26*2.54 -> 8.89
A27: 16 | C27: 16 | D27: Small box | H27: 6 | L27: 6 | R27: 6 | W27: =AA27&"*"&AB27&"*"&AC27 -> 25.4*22.86*8.89 | X27: 10 | Y27: 9 | Z27: 3.5 | AA27: =+X27*2.54 -> 25.4 | AB27: =+Y27*2.54 -> 22.86 | AC27: =+Z27*2.54 -> 8.89
M28: 100 | AA28: =+X28*2.54 -> 0 | AB28: =+Y28*2.54 -> 0 | AC28: =+Z28*2.54 -> 0
A29: 17 | C29: 17 | E29: NESSB711 | F29: 655 DESERT PINK | G29: 655 | H29: 36 | J29: 36 | Q29: 1 | R29: 36 | S29: =+U29/Q29 -> 3.32 | T29: =+V29/Q29 -> 4.32 | U29: 3.32 | V29: 4.32 | W29: =AA29&"*"&AB29&"*"&AC29 -> 50.8*43.18*11.43 | X29: 20 | Y29: 17 | Z29: 4.5 | AA29: =+X29*2.54 -> 50.8 | AB29: =+Y29*2.54 -> 43.18 | AC29: =+Z29*2.54 -> 11.43
A30: 18 | C30: 18 | H30: 36 | K30: 36 | Q30: 1 | R30: 36 | S30: =+U30/Q30 -> 3.64 | T30: =+V30/Q30 -> 4.64 | U30: 3.64 | V30: 4.64 | W30: =AA30&"*"&AB30&"*"&AC30 -> 50.8*43.18*11.43 | X30: 20 | Y30: 17 | Z30: 4.5 | AA30: =+X30*2.54 -> 50.8 | AB30: =+Y30*2.54 -> 43.18 | AC30: =+Z30*2.54 -> 11.43
A31: 19 | C31: 19 | H31: 39 | K31: 39 | Q31: 1 | R31: 39 | S31: =+U31/Q31 -> 3.94 | T31: =+V31/Q31 -> 4.96 | U31: 3.94 | V31: 4.96 | W31: =AA31&"*"&AB31&"*"&AC31 -> 50.8*43.18*12.7 | X31: 20 | Y31: 17 | Z31: 5 | AA31: =+X31*2.54 -> 50.8 | AB31: =+Y31*2.54 -> 43.18 | AC31: =+Z31*2.54 -> 12.7
A32: 20 | C32: 20 | H32: 36 | L32: 36 | Q32: 1 | R32: 36 | S32: =+U32/Q32 -> 3.93 | T32: =+V32/Q32 -> 4.96 | U32: 3.93 | V32: 4.96 | W32: =AA32&"*"&AB32&"*"&AC32 -> 50.8*43.18*11.43 | X32: 20 | Y32: 17 | Z32: 4.5 | AA32: =+X32*2.54 -> 50.8 | AB32: =+Y32*2.54 -> 43.18 | AC32: =+Z32*2.54 -> 11.43
A33: 21 | C33: 21 | H33: 39 | L33: 39 | Q33: 1 | R33: 39 | S33: =+U33/Q33 -> 4.26 | T33: =+V33/Q33 -> 5.3 | U33: 4.26 | V33: 5.3 | W33: =AA33&"*"&AB33&"*"&AC33 -> 50.8*43.18*12.7 | X33: 20 | Y33: 17 | Z33: 5 | AA33: =+X33*2.54 -> 50.8 | AB33: =+Y33*2.54 -> 43.18 | AC33: =+Z33*2.54 -> 12.7
A34: 22 | C34: 22 | H34: 36 | M34: 36 | Q34: 1 | R34: 36 | S34: =+U34/Q34 -> 4.25 | T34: =+V34/Q34 -> 5.28 | U34: 4.25 | V34: 5.28 | W34: =AA34&"*"&AB34&"*"&AC34 -> 50.8*43.18*12.7 | X34: 20 | Y34: 17 | Z34: 5 | AA34: =+X34*2.54 -> 50.8 | AB34: =+Y34*2.54 -> 43.18 | AC34: =+Z34*2.54 -> 12.7
A35: 23 | C35: 23 | D35: ODD CARTON | H35: 14 | J35: 14 | Q35: 1 | R35: 14 | S35: =+U35/Q35 -> 1.29 | T35: =+V35/Q35 -> 2.19 | U35: 1.29 | V35: 2.19 | W35: =AA35&"*"&AB35&"*"&AC35 -> 44.45*25.4*7.62 | X35: 17.5 | Y35: 10 | Z35: 3 | AA35: =+X35*2.54 -> 44.45 | AB35: =+Y35*2.54 -> 25.4 | AC35: =+Z35*2.54 -> 7.62
A36: 24 | C36: 24 | D36: ODD CARTON | H36: 14 | M36: 14 | Q36: 1 | R36: 14 | S36: =+U36/Q36 -> 1.65 | T36: =+V36/Q36 -> 2.51 | U36: 1.65 | V36: 2.51 | W36: =AA36&"*"&AB36&"*"&AC36 -> 44.45*25.4*7.62 | X36: 17.5 | Y36: 10 | Z36: 3 | AA36: =+X36*2.54 -> 44.45 | AB36: =+Y36*2.54 -> 25.4 | AC36: =+Z36*2.54 -> 7.62
M37: 50
M39: =SUM(M19:M38) -> 264 | N39: =SUM(N19:N38) -> 0 | O39: =SUM(O19:O38) -> 0 | P39: =SUM(P19:P38) -> 0 | Q39: =SUM(Q19:Q38) -> 23 | R39: =SUM(R19:R38) -> 750 | U39: =SUM(U19:U38) -> 78.86 | V39: =SUM(V19:V38) -> 101.65
D42: CUSTOMER PO | E42: Style | F42: Color | G42: Color Code | H42: xs | I42: S | J42: M | K42: L | L42: XL | Q42: TOT CTNS | R42: TOT PCS
D43: DV7 | E43: NESSB711 | F43: BLACK | G43: 001 | I43: 100 | J43: 150 | K43: 150 | L43: 100 | Q43: 15 | R43: 500 | X43: =+SUM(H43:L43) -> 500 | Y43: =+R43-X43 -> 0
D44: DV7 | E44: NESSB711 | F44: DESERT PINK | G44: 655 | I44: 50 | J44: 75 | K44: 75 | L44: 50 | Q44: 8 | R44: 250 | X44: =+SUM(H44:L44) -> 250 | Y44: =+R44-X44 -> 0
K46: TOTAL | Q46: =SUM(Q43:Q44) -> 23 | R46: =SUM(R43:R44) -> 750

Sheet IRREGULAR SS PLDV7
A4: PACKING LIST
H5: PEI
A6: ISSUE TO : | E6: =+'[1]INVOICE 11'!C7 -> SUPREME INTERNATIONAL, LLC | H6: STYLE:
H7: LABEL
H8: P.O.:
H9: PCS
H10: SIZES
A12: PAYMENT: T/C | H12: MADE IN
A13: PO NO: | B13: DV7 | H13: C# UP
A14: CUSTOMER PO.: | E14: =+B13 -> DV7
A15: INVOICE NO: | D15: =+'INVOICE 94'!M2 -> 7726477
A16: Detail Breakdown
A18: CASE FROM-TO | D18: REMARKS | E18: Style | F18: Color Name | G18: Color code | H18: Units/case | I18: xs | J18: S | K18: M | L18: L | M18: 4 | N18: 5 | O18: 6 | P18: 6X | Q18: TOT CTNS | R18: TOT PCS | S18: NW | T18: GW | U18: TTL NW | V18: TTL GW | W18: CARTON SIZE ( CM)
A19: 1 | C19: 2 | E19: NESSB711 | F19: 001 BLACK | G19: 001 | H19: 36 | J19: 36 | Q19: 2 | R19: 72 | S19: =+U19/Q19 -> 3.32 | T19: =+V19/Q19 -> 4.32 | U19: 6.64 | V19: 8.64 | W19: =AA19&"*"&AB19&"*"&AC19 -> 50.8*43.18*11.43 | X19: 20 | Y19: 17 | Z19: 4.5 | AA19: =+X19*2.54 -> 50.8 | AB19: =+Y19*2.54 -> 43.18 | AC19: =+Z19*2.54 -> 11.43
A20: 3 | C20: 6 | H20: 36 | K20: 36 | Q20: 4 | R20: 144 | S20: =+U20/Q20 -> 3.64 | T20: =+V20/Q20 -> 4.64 | U20: 14.56 | V20: 18.56 | W20: =AA20&"*"&AB20&"*"&AC20 -> 50.8*43.18*11.43 | X20: 20 | Y20: 17 | Z20: 4.5 | AA20: =+X20*2.54 -> 50.8 | AB20: =+Y20*2.54 -> 43.18 | AC20: =+Z20*2.54 -> 11.43
A21: 7 | C21: 10 | H21: 36 | L21: 36 | Q21: 4 | R21: 144 | S21: =+U21/Q21 -> 3.93 | T21: =+V21/Q21 -> 4.96 | U21: 15.72 | V21: 19.84 | W21: =AA21&"*"&AB21&"*"&AC21 -> 50.8*43.18*12.7 | X21: 20 | Y21: 17 | Z21: 5 | AA21: =+X21*2.54 -> 50.8 | AB21: =+Y21*2.54 -> 43.18 | AC21: =+Z21*2.54 -> 12.7
A22: 11 | C22: 12 | H22: 36 | M22: 36 | Q22: 2 | R22: 72 | S22: =+U22/Q22 -> 4.25 | T22: =+V22/Q22 -> 5.28 | U22: 8.5 | V22: 10.56 | W22: =AA22&"*"&AB22&"*"&AC22 -> 50.8*43.18*12.7 | X22: 20 | Y22: 17 | Z22: 5 | AA22: =+X22*2.54 -> 50.8 | AB22: =+Y22*2.54 -> 43.18 | AC22: =+Z22*2.54 -> 12.7
A23: 13 | C23: 13 | D23: ODD CARTON | H23: 28 | J23: 28 | Q23: 1 | R23: 28 | S23: =+U23/Q23 -> 2.58 | T23: =+V23/Q23 -> 3.48 | U23: 2.58 | V23: 3.48 | W23: =AA23&"*"&AB23&"*"&AC23 -> 50.8*43.18*10.16 | X23: 20 | Y23: 17 | Z23: 4 | AA23: =+X23*2.54 -> 50.8 | AB23: =+Y23*2.54 -> 43.18 | AC23: =+Z23*2.54 -> 10.16
A24: 14 | C24: 14 | D24: ODD CARTON | H24: 28 | M24: 28 | Q24: 1 | R24: 28 | S24: =+U24/Q24 -> 3.3 | T24: =+V24/Q24 -> 4.27 | U24: 3.3 | V24: 4.27 | W24: =AA24&"*"&AB24&"*"&AC24 -> 50.8*43.18*11.43 | X24: 20 | Y24: 17 | Z24: 4.5 | AA24: =+X24*2.54 -> 50.8 | AB24: =+Y24*2.54 -> 43.18 | AC24: =+Z24*2.54 -> 11.43
A25: Master box 15-16 | D25: Master box | W25: =AA25&"*"&AB25&"*"&AC25 -> 48.26*27.94*11.43 | X25: 19 | Y25: 11 | Z25: 4.5 | AA25: =+X25*2.54 -> 48.26 | AB25: =+Y25*2.54 -> 27.94 | AC25: =+Z25*2.54 -> 11.43
A26: 15 | C26: 15 | D26: Small box | H26: 6 | K26: 6 | Q26: 1 | R26: 6 | S26: =+U26/Q26 -> 1.28 | T26: =+V26/Q26 -> 2.14 | U26: 1.28 | V26: 2.14 | W26: =AA26&"*"&AB26&"*"&AC26 -> 25.4*22.86*8.89 | X26: 10 | Y26: 9 | Z26: 3.5 | AA26: =+X26*2.54 -> 25.4 | AB26: =+Y26*2.54 -> 22.86 | AC26: =+Z26*2.54 -> 8.89
A27: 16 | C27: 16 | D27: Small box | H27: 6 | L27: 6 | Q27: 1 | R27: 6 | W27: =AA27&"*"&AB27&"*"&AC27 -> 25.4*22.86*8.89 | X27: 10 | Y27: 9 | Z27: 3.5 | AA27: =+X27*2.54 -> 25.4 | AB27: =+Y27*2.54 -> 22.86 | AC27: =+Z27*2.54 -> 8.89
M28: 100 | AA28: =+X28*2.54 -> 0 | AB28: =+Y28*2.54 -> 0 | AC28: =+Z28*2.54 -> 0
A29: 17 | C29: 17 | E29: NESSB711 | F29: 655 DESERT PINK | G29: 655 | H29: 36 | J29: 36 | Q29: 1 | R29: 36 | S29: =+U29/Q29 -> 3.32 | T29: =+V29/Q29 -> 4.32 | U29: 3.32 | V29: 4.32 | W29: =AA29&"*"&AB29&"*"&AC29 -> 50.8*43.18*11.43 | X29: 20 | Y29: 17 | Z29: 4.5 | AA29: =+X29*2.54 -> 50.8 | AB29: =+Y29*2.54 -> 43.18 | AC29: =+Z29*2.54 -> 11.43
A30: 18 | C30: 18 | H30: 36 | K30: 36 | Q30: 1 | R30: 36 | S30: =+U30/Q30 -> 3.64 | T30: =+V30/Q30 -> 4.64 | U30: 3.64 | V30: 4.64 | W30: =AA30&"*"&AB30&"*"&AC30 -> 50.8*43.18*11.43 | X30: 20 | Y30: 17 | Z30: 4.5 | AA30: =+X30*2.54 -> 50.8 | AB30: =+Y30*2.54 -> 43.18 | AC30: =+Z30*2.54 -> 11.43
A31: 19 | C31: 19 | H31: 39 | K31: 39 | Q31: 1 | R31: 39 | S31: =+U31/Q31 -> 3.94 | T31: =+V31/Q31 -> 4.96 | U31: 3.94 | V31: 4.96 | W31: =AA31&"*"&AB31&"*"&AC31 -> 50.8*43.18*12.7 | X31: 20 | Y31: 17 | Z31: 5 | AA31: =+X31*2.54 -> 50.8 | AB31: =+Y31*2.54 -> 43.18 | AC31: =+Z31*2.54 -> 12.7
A32: 20 | C32: 20 | H32: 36 | L32: 36 | Q32: 1 | R32: 36 | S32: =+U32/Q32 -> 3.93 | T32: =+V32/Q32 -> 4.96 | U32: 3.93 | V32: 4.96 | W32: =AA32&"*"&AB32&"*"&AC32 -> 50.8*43.18*11.43 | X32: 20 | Y32: 17 | Z32: 4.5 | AA32: =+X32*2.54 -> 50.8 | AB32: =+Y32*2.54 -> 43.18 | AC32: =+Z32*2.54 -> 11.43
A33: 21 | C33: 21 | H33: 39 | L33: 39 | Q33: 1 | R33: 39 | S33: =+U33/Q33 -> 4.26 | T33: =+V33/Q33 -> 5.3 | U33: 4.26 | V33: 5.3 | W33: =AA33&"*"&AB33&"*"&AC33 -> 50.8*43.18*12.7 | X33: 20 | Y33: 17 | Z33: 5 | AA33: =+X33*2.54 -> 50.8 | AB33: =+Y33*2.54 -> 43.18 | AC33: =+Z33*2.54 -> 12.7
A34: 22 | C34: 22 | H34: 36 | M34: 36 | Q34: 1 | R34: 36 | S34: =+U34/Q34 -> 4.25 | T34: =+V34/Q34 -> 5.28 | U34: 4.25 | V34: 5.28 | W34: =AA34&"*"&AB34&"*"&AC34 -> 50.8*43.18*12.7 | X34: 20 | Y34: 17 | Z34: 5 | AA34: =+X34*2.54 -> 50.8 | AB34: =+Y34*2.54 -> 43.18 | AC34: =+Z34*2.54 -> 12.7
A35: 23 | C35: 23 | D35: ODD CARTON | H35: 14 | J35: 14 | Q35: 1 | R35: 14 | S35: =+U35/Q35 -> 1.29 | T35: =+V35/Q35 -> 2.19 | U35: 1.29 | V35: 2.19 | W35: =AA35&"*"&AB35&"*"&AC35 -> 44.45*25.4*7.62 | X35: 17.5 | Y35: 10 | Z35: 3 | AA35: =+X35*2.54 -> 44.45 | AB35: =+Y35*2.54 -> 25.4 | AC35: =+Z35*2.54 -> 7.62
A36: 24 | C36: 24 | D36: ODD CARTON | H36: 14 | M36: 14 | Q36: 1 | R36: 14 | S36: =+U36/Q36 -> 1.65 | T36: =+V36/Q36 -> 2.51 | U36: 1.65 | V36: 2.51 | W36: =AA36&"*"&AB36&"*"&AC36 -> 44.45*25.4*7.62 | X36: 17.5 | Y36: 10 | Z36: 3 | AA36: =+X36*2.54 -> 44.45 | AB36: =+Y36*2.54 -> 25.4 | AC36: =+Z36*2.54 -> 7.62
M37: 50
M39: =SUM(M19:M38) -> 264 | N39: =SUM(N19:N38) -> 0 | O39: =SUM(O19:O38) -> 0 | P39: =SUM(P19:P38) -> 0 | Q39: =SUM(Q19:Q38) -> 24 | R39: =SUM(R19:R38) -> 750 | U39: =SUM(U19:U38) -> 78.86 | V39: =SUM(V19:V38) -> 101.65
D42: CUSTOMER PO | E42: Style | F42: Color | G42: Color Code | H42: xs | I42: S | J42: M | K42: L | L42: XL | Q42: TOT CTNS | R42: TOT PCS
D43: DV7 | E43: NESSB711 | F43: BLACK | G43: 001 | I43: 100 | J43: 150 | K43: 150 | L43: 100 | Q43: 16 | R43: 500 | X43: =+SUM(H43:L43) -> 500 | Y43: =+R43-X43 -> 0
D44: DV7 | E44: NESSB711 | F44: DESERT PINK | G44: 655 | I44: 50 | J44: 75 | K44: 75 | L44: 50 | Q44: 8 | R44: 250 | X44: =+SUM(H44:L44) -> 250 | Y44: =+R44-X44 -> 0
K46: TOTAL | Q46: =SUM(Q43:Q44) -> 24 | R46: =SUM(R43:R44) -> 750

Sheet SOLID PL EQ349
A4: PACKING LIST
H5: PEI
A6: ISSUE TO : | E6: =+'[1]INVOICE 11'!C7 -> SUPREME INTERNATIONAL, LLC | H6: STYLE:
H7: LABEL
H8: P.O.:
H9: PCS
H10: SIZES
A12: PAYMENT: T/C | H12: MADE IN
A13: PO NO: | B13: EQ349 | H13: C# UP
A14: CUSTOMER PO.: | E14: =+B13 -> EQ349
A15: INVOICE NO: | D15: =+'INVOICE 94'!M2 -> 7726477
A16: Detail Breakdown
A18: CASE FROM-TO | D18: REMARKS | E18: Style | F18: Color Name | G18: Color code | H18: Units/case | I18: xs | J18: S | K18: M | L18: L | M18: 4 | N18: 5 | O18: 6 | P18: 6X | Q18: TOT CTNS | R18: TOT PCS | S18: NW | T18: GW | U18: TTL NW | V18: TTL GW | W18: CARTON SIZE ( CM)
A19: 1 | C19: 1 | E19: NESSB711 | F19: 385 ENERGY | G19: 385 | H19: 16 | J19: 16 | Q19: 1 | R19: 16 | S19: =+U19/Q19 -> 1.61 | T19: =+V19/Q19 -> 2.54 | U19: 1.61 | V19: 2.54 | W19: =AA19&"*"&AB19&"*"&AC19 -> 50.8*43.18*7.62 | X19: 20 | Y19: 17 | Z19: 3 | AA19: =+X19*2.54 -> 50.8 | AB19: =+Y19*2.54 -> 43.18 | AC19: =+Z19*2.54 -> 7.62
A20: 2 | C20: 2 | H20: 16 | K20: 16 | Q20: 1 | R20: 16 | S20: =+U20/Q20 -> 1.74 | T20: =+V20/Q20 -> 2.63 | U20: 1.74 | V20: 2.63 | W20: =AA20&"*"&AB20&"*"&AC20 -> 50.8*43.18*7.62 | X20: 20 | Y20: 17 | Z20: 3 | AA20: =+X20*2.54 -> 50.8 | AB20: =+Y20*2.54 -> 43.18 | AC20: =+Z20*2.54 -> 7.62
A21: Master box 3-4 | D21: Master box | W21: =AA21&"*"&AB21&"*"&AC21 -> 48.26*27.94*11.43 | X21: 19 | Y21: 11 | Z21: 4.5 | AA21: =+X21*2.54 -> 48.26 | AB21: =+Y21*2.54 -> 27.94 | AC21: =+Z21*2.54 -> 11.43
A22: 3 | C22: 3 | D22: Small box | H22: 8 | I22: 8 | M22: 36 | Q22: 1 | R22: 8 | S22: =+U22/Q22 -> 1.14 | T22: =+V22/Q22 -> 2.09 | U22: 1.14 | V22: 2.09 | W22: =AA22&"*"&AB22&"*"&AC22 -> 25.4*22.86*8.89 | X22: 10 | Y22: 9 | Z22: 3.5 | AA22: =+X22*2.54 -> 25.4 | AB22: =+Y22*2.54 -> 22.86 | AC22: =+Z22*2.54 -> 8.89
A23: 4 | C23: 4 | D23: Small box | H23: 8 | L23: 8 | R23: 8 | W23: =AA23&"*"&AB23&"*"&AC23 -> 25.4*22.86*8.89 | X23: 10 | Y23: 9 | Z23: 3.5 | AA23: =+X23*2.54 -> 25.4 | AB23: =+Y23*2.54 -> 22.86 | AC23: =+Z23*2.54 -> 8.89
M24: 50
M26: =SUM(M19:M25) -> 86 | N26: =SUM(N19:N25) -> 0 | O26: =SUM(O19:O25) -> 0 | P26: =SUM(P19:P25) -> 0 | Q26: =SUM(Q19:Q25) -> 3 | R26: =SUM(R19:R25) -> 48 | U26: =SUM(U19:U25) -> 4.49 | V26: =SUM(V19:V25) -> 7.26
D29: CUSTOMER PO | E29: Style | F29: Color | G29: Color Code | H29: xs | I29: S | J29: M | K29: L | L29: XL | Q29: TOT CTNS | R29: TOT PCS
D30: EQ349 | E30: NESSB711 | F30: ENERGY | G30: 385 | H30: 8 | I30: 16 | J30: 16 | K30: 8 | Q30: 3 | R30: 48 | X30: =+SUM(H30:L30) -> 48 | Y30: =+R30-X30 -> 0
K33: TOTAL | Q33: =SUM(Q30:Q31) -> 3 | R33: =SUM(R30:R31) -> 48

Sheet IRREGULAR SS PL EQ349
A4: PACKING LIST
H5: PEI
A6: ISSUE TO : | E6: =+'[1]INVOICE 11'!C7 -> SUPREME INTERNATIONAL, LLC | H6: STYLE:
H7: LABEL
H8: P.O.:
H9: PCS
H10: SIZES
A12: PAYMENT: T/C | H12: MADE IN
A13: PO NO: | B13: EQ349 | H13: C# UP
A14: CUSTOMER PO.: | E14: =+B13 -> EQ349
A15: INVOICE NO: | D15: =+'INVOICE 94'!M2 -> 7726477
A16: Detail Breakdown
A18: CASE FROM-TO | D18: REMARKS | E18: Style | F18: Color Name | G18: Color code | H18: Units/case | I18: xs | J18: S | K18: M | L18: L | M18: 4 | N18: 5 | O18: 6 | P18: 6X | Q18: TOT CTNS | R18: TOT PCS | S18: NW | T18: GW | U18: TTL NW | V18: TTL GW | W18: CARTON SIZE ( CM)
A19: 1 | C19: 1 | E19: NESSB711 | F19: 385 ENERGY | G19: 385 | H19: 16 | J19: 16 | Q19: 1 | R19: 16 | S19: =+U19/Q19 -> 1.61 | T19: =+V19/Q19 -> 2.54 | U19: 1.61 | V19: 2.54 | W19: =AA19&"*"&AB19&"*"&AC19 -> 50.8*43.18*7.62 | X19: 20 | Y19: 17 | Z19: 3 | AA19: =+X19*2.54 -> 50.8 | AB19: =+Y19*2.54 -> 43.18 | AC19: =+Z19*2.54 -> 7.62
A20: 2 | C20: 2 | H20: 16 | K20: 16 | Q20: 1 | R20: 16 | S20: =+U20/Q20 -> 1.74 | T20: =+V20/Q20 -> 2.63 | U20: 1.74 | V20: 2.63 | W20: =AA20&"*"&AB20&"*"&AC20 -> 50.8*43.18*7.62 | X20: 20 | Y20: 17 | Z20: 3 | AA20: =+X20*2.54 -> 50.8 | AB20: =+Y20*2.54 -> 43.18 | AC20: =+Z20*2.54 -> 7.62
A21: Master box 3-4 | D21: Master box | W21: =AA21&"*"&AB21&"*"&AC21 -> 48.26*27.94*11.43 | X21: 19 | Y21: 11 | Z21: 4.5 | AA21: =+X21*2.54 -> 48.26 | AB21: =+Y21*2.54 -> 27.94 | AC21: =+Z21*2.54 -> 11.43
A22: 3 | C22: 3 | D22: Small box | H22: 8 | I22: 8 | M22: 36 | Q22: 1 | R22: 8 | S22: =+U22/Q22 -> 1.14 | T22: =+V22/Q22 -> 2.09 | U22: 1.14 | V22: 2.09 | W22: =AA22&"*"&AB22&"*"&AC22 -> 25.4*22.86*8.89 | X22: 10 | Y22: 9 | Z22: 3.5 | AA22: =+X22*2.54 -> 25.4 | AB22: =+Y22*2.54 -> 22.86 | AC22: =+Z22*2.54 -> 8.89
A23: 4 | C23: 4 | D23: Small box | H23: 8 | L23: 8 | Q23: 1 | R23: 8 | W23: =AA23&"*"&AB23&"*"&AC23 -> 25.4*22.86*8.89 | X23: 10 | Y23: 9 | Z23: 3.5 | AA23: =+X23*2.54 -> 25.4 | AB23: =+Y23*2.54 -> 22.86 | AC23: =+Z23*2.54 -> 8.89
M24: 50
M26: =SUM(M19:M25) -> 86 | N26: =SUM(N19:N25) -> 0 | O26: =SUM(O19:O25) -> 0 | P26: =SUM(P19:P25) -> 0 | Q26: =SUM(Q19:Q25) -> 4 | R26: =SUM(R19:R25) -> 48 | U26: =SUM(U19:U25) -> 4.49 | V26: =SUM(V19:V25) -> 7.26
D29: CUSTOMER PO | E29: Style | F29: Color | G29: Color Code | H29: xs | I29: S | J29: M | K29: L | L29: XL | Q29: TOT CTNS | R29: TOT PCS
D30: EQ349 | E30: NESSB711 | F30: ENERGY | G30: 385 | H30: 8 | I30: 16 | J30: 16 | K30: 8 | Q30: 4 | R30: 48 | X30: =+SUM(H30:L30) -> 48 | Y30: =+R30-X30 -> 0
K33: TOTAL | Q33: =SUM(Q30:Q31) -> 4 | R33: =SUM(R30:R31) -> 48

Sheet SOLID PL EV154
A4: PACKING LIST
G5: PEI
A6: ISSUE TO : | D6: =+'[1]INVOICE 11'!C7 -> SUPREME INTERNATIONAL, LLC | G6: STYLE:
G7: LABEL
G8: P.O.:
G9: PCS
G10: SIZES
A12: PAYMENT: T/C | G12: MADE IN
A13: PO NO: | B13: EV154 | G13: C# UP
A14: CUSTOMER PO.: | D14: =+B13 -> EV154
A15: INVOICE NO: | C15: =+'INVOICE 94'!M2 -> 7726477
A16: Detail Breakdown
A18: CASE FROM-TO | C18: REMARKS | D18: Style | E18: Color Name | F18: Color code | G18: Units/case | H18: xs | I18: S | J18: M | K18: L | L18: 4 | M18: 5 | N18: 6 | O18: 6X | P18: TOT CTNS | Q18: TOT PCS | R18: NW | S18: GW | T18: TTL NW | U18: TTL GW | V18: CARTON SIZE ( CM)
A19: 1 | B19: 1 | D19: NESSB711 | E19: 001 BLACK | F19: 001 | G19: 8 | H19: 8 | P19: 1 | Q19: 8 | R19: =+T19/P19 -> 0.7 | S19: =+U19/P19 -> 1 | T19: 0.7 | U19: 1 | V19: =Z19&"*"&AA19&"*"&AB19 -> 25.4*22.86*8.89 | W19: 10 | X19: 9 | Y19: 3.5 | Z19: =+W19*2.54 -> 25.4 | AA19: =+X19*2.54 -> 22.86 | AB19: =+Y19*2.54 -> 8.89
A20: 2 | B20: 2 | G20: 25 | I20: 25 | P20: 1 | Q20: 25 | R20: =+T20/P20 -> 2.42 | S20: =+U20/P20 -> 3.38 | T20: 2.42 | U20: 3.38 | V20: =Z20&"*"&AA20&"*"&AB20 -> 50.8*43.18*8.89 | W20: 20 | X20: 17 | Y20: 3.5 | Z20: =+W20*2.54 -> 50.8 | AA20: =+X20*2.54 -> 43.18 | AB20: =+Y20*2.54 -> 8.89
A21: 3 | B21: 3 | G21: 32 | J21: 32 | P21: 1 | Q21: 32 | R21: =+T21/P21 -> 3.16 | S21: =+U21/P21 -> 4.14 | T21: 3.16 | U21: 4.14 | V21: =Z21&"*"&AA21&"*"&AB21 -> 50.8*43.18*10.16 | W21: 20 | X21: 17 | Y21: 4 | Z21: =+W21*2.54 -> 50.8 | AA21: =+X21*2.54 -> 43.18 | AB21: =+Y21*2.54 -> 10.16
A22: 4 | B22: 4 | G22: 31 | K22: 31 | P22: 1 | Q22: 31 | R22: =+T22/P22 -> 3.7 | S22: =+U22/P22 -> 4.7 | T22: 3.7 | U22: 4.7 | V22: =Z22&"*"&AA22&"*"&AB22 -> 50.8*43.18*11.43 | W22: 20 | X22: 17 | Y22: 4.5 | Z22: =+W22*2.54 -> 50.8 | AA22: =+X22*2.54 -> 43.18 | AB22: =+Y22*2.54 -> 11.43
